Workbook

Sheet Бюджет
B2: Годовая нагрузка преподавателей | U2: Годовая нагрузка преподавателей
B3: на 2025-2026 учебный год (бюджет) | U3: на 2025-2026 учебный год (бюджет)
B5: Ф.И.О. | D5: Группа | E5: Кол-во ст. | F5: Подг | G5: Нагрузка | I5: Кол-во часов I полугодие | M5: Нагрузка | O5: Кол-во часов II полугодие | S5: Всего за учебный год | U5: № | V5: Ф.И.О. | W5: Предмет | X5: Количество часов
G6: Лек. | H6: Практ., семин., лаб. | I6: Лек. | J6: Практ., семин., лаб. | K6: Итого | L6: Тест | M6: Лек. | N6: Практ., семин., лаб. | O6: Лек. | P6: Практ., семин., лаб. | Q6: Итого | R6: Тест | X6: Итого I полугодие | Y6: Итого II полугодие | Z6: Всего за учебный год
B7: № | G7: I полугодие | M7: II полугодие | AB7: Кол-во
B8: 1 | D8: Хирургия | G8: =SUM(G9,G16,G18,G22,G25,G27) -> 477 | M8: =SUM(M9,M16,M18,M22,M25,M27) -> 510 | S8: =SUM(S9,S16,S18,S22,S25,S27) -> 987 | U8: 1 | V8: Абдиева Ж. | W8: ОСД | X8: =SUMIF($B$8:$B$591,$V8,G$8:G$591) -> 160 | Y8: =SUMIF($B$8:$B$591,$V8,M$8:M$591) -> 118 | Z8: =SUM(X8:Y8) -> 278 | AB8: =COUNTIF(V$8:V$85,V8) -> 1
B9: Жакыпбеков К.Ш. | G9: =SUM(K10:L15) -> 126 | M9: =SUM(Q10:R15) -> 66 | S9: =SUM(G9:Q9) -> 192 | U9: 2 | V9: Абдрахманова Ж. | W9: Инфек контроль | X9: =SUMIF($B$8:$B$591,$V9,G$8:G$591) -> 93 | Y9: =SUMIF($B$8:$B$591,$V9,M$8:M$591) -> 0 | Z9: =SUM(X9:Y9) -> 93 | AB9: =COUNTIF(V$8:V$85,V9) -> 1
C10: 1 | D10: СД-21 | E10: 20 | F10: =IF(E10<15,1,IF(((E10>=15)*(E10<23)),2,3)) -> 2 | I10: =G10 -> 0 | J10: =IF(H10=0,0,H10*$F10) -> 0 | K10: =SUM(I10:J10) -> 0 | M10: 18 | O10: =M10 -> 18 | P10: =IF(N10=0,0,N10*$F10) -> 0 | Q10: =SUM(O10:P10) -> 18 | S10: =SUM(K10:L10,Q10:R10) -> 18 | U10: 3 | V10: Абдуллаева М.Н. | W10: Инф контроль | X10: =SUMIF($B$8:$B$591,$V10,G$8:G$591) -> 18 | Y10: =SUMIF($B$8:$B$591,$V10,M$8:M$591) -> 52 | Z10: =SUM(X10:Y10) -> 70 | AB10: =COUNTIF(V$8:V$85,V10) -> 1
C11: 2 | D11: АД-21 | E11: 13 | F11: =IF(E11<15,1,IF(((E11>=15)*(E11<23)),2,3)) -> 1 | G11: 18 | H11: 42 | I11: =G11 -> 18 | J11: =IF(H11=0,0,H11*$F11) -> 42 | K11: =SUM(I11:J11) -> 60 | L11: 12 | M11: 12 | O11: =M11 -> 12 | P11: =IF(N11=0,0,N11*$F11) -> 0 | Q11: =SUM(O11:P11) -> 12 | S11: =SUM(K11:L11,Q11:R11) -> 84 | U11: 4 | V11: Абдуллаева М.Н. ШТ | W11: ОСД | X11: =SUMIF($B$8:$B$591,$V11,G$8:G$591) -> 12 | Y11: =SUMIF($B$8:$B$591,$V11,M$8:M$591) -> 8 | Z11: =SUM(X11:Y11) -> 20 | AB11: =COUNTIF(V$8:V$85,V11) -> 1
C12: 3 | D12: СД-31 | E12: 25 | F12: =IF(E12<15,1,IF(((E12>=15)*(E12<23)),2,3)) -> 3 | G12: 12 | I12: =G12 -> 12 | J12: =IF(H12=0,0,H12*$F12) -> 0 | K12: =SUM(I12:J12) -> 12 | M12: 12 | O12: =M12 -> 12 | P12: =IF(N12=0,0,N12*$F12) -> 0 | Q12: =SUM(O12:P12) -> 12 | S12: =SUM(K12:L12,Q12:R12) -> 24 | U12: 5 | V12: Абдыкеримова А.Н. | W12: Химия | X12: =SUMIF($B$8:$B$591,$V12,G$8:G$591) -> 354 | Y12: =SUMIF($B$8:$B$591,$V12,M$8:M$591) -> 296 | Z12: =SUM(X12:Y12) -> 650 | AB12: =COUNTIF(V$8:V$85,V12) -> 1
C13: 4 | D13: ЛД-31 | E13: 25 | F13: =IF(E13<15,1,IF(((E13>=15)*(E13<23)),2,3)) -> 3 | G13: 24 | I13: =G13 -> 24 | J13: =IF(H13=0,0,H13*$F13) -> 0 | K13: =SUM(I13:J13) -> 24 | M13: 12 | O13: =M13 -> 12 | P13: =IF(N13=0,0,N13*$F13) -> 0 | Q13: =SUM(O13:P13) -> 12 | S13: =SUM(K13:L13,Q13:R13) -> 36 | U13: 6 | V13: Абдыкеримова К. | W13: Основы реабилитации (физиотерапия) | X13: =SUMIF($B$8:$B$591,$V13,G$8:G$591) -> 243 | Y13: =SUMIF($B$8:$B$591,$V13,M$8:M$591) -> 0 | Z13: =SUM(X13:Y13) -> 243 | AB13: =COUNTIF(V$8:V$85,V13) -> 1
C14: 5 | D14: ЛД-41 | E14: 25 | F14: =IF(E14<15,1,IF(((E14>=15)*(E14<23)),2,3)) -> 3 | G14: 18 | I14: =G14 -> 18 | J14: =IF(H14=0,0,H14*$F14) -> 0 | K14: =SUM(I14:J14) -> 18 | O14: =M14 -> 0 | P14: =IF(N14=0,0,N14*$F14) -> 0 | Q14: =SUM(O14:P14) -> 0 | S14: =SUM(K14:L14,Q14:R14) -> 18 | U14: 7 | V14: Азизова Н. | W14: СМ | X14: =SUMIF($B$8:$B$591,$V14,G$8:G$591) -> 261 | Y14: =SUMIF($B$8:$B$591,$V14,M$8:M$591) -> 138 | Z14: =SUM(X14:Y14) -> 399 | AB14: =COUNTIF(V$8:V$85,V14) -> 1
C15: 6 | D15: ЛД-21 | E15: 25 | F15: =IF(E15<15,1,IF(((E15>=15)*(E15<23)),2,3)) -> 3 | I15: =G15 -> 0 | J15: =IF(H15=0,0,H15*$F15) -> 0 | K15: =SUM(I15:J15) -> 0 | M15: 12 | O15: =M15 -> 12 | P15: =IF(N15=0,0,N15*$F15) -> 0 | Q15: =SUM(O15:P15) -> 12 | S15: =SUM(K15:L15,Q15:R15) -> 12 | U15: 8 | V15: Акимканова А. | W15: ОСД | X15: =SUMIF($B$8:$B$591,$V15,G$8:G$591) -> 96 | Y15: =SUMIF($B$8:$B$591,$V15,M$8:M$591) -> 0 | Z15: =SUM(X15:Y15) -> 96 | AB15: =COUNTIF(V$8:V$85,V15) -> 1
B16: Акунова Ч. ВНЕШТ | G16: =SUM(K17:L17) -> 0 | M16: =SUM(Q17:R17) -> 45 | S16: =SUM(G16:Q16) -> 45 | U16: 9 | V16: Акматова Ж. | W16: Гинекология | X16: =SUMIF($B$8:$B$591,$V16,G$8:G$591) -> 0 | Y16: =SUMIF($B$8:$B$591,$V16,M$8:M$591) -> 42 | Z16: =SUM(X16:Y16) -> 42 | AB16: =COUNTIF(V$8:V$85,V16) -> 1
C17: 2 | D17: АД-21 | E17: 13 | F17: =IF(E17<15,1,IF(((E17>=15)*(E17<23)),2,3)) -> 1 | I17: =G17 -> 0 | J17: =IF(H17=0,0,H17*$F17) -> 0 | K17: =SUM(I17:J17) -> 0 | N17: 33 | O17: =M17 -> 0 | P17: =IF(N17=0,0,N17*$F17) -> 33 | Q17: =SUM(O17:P17) -> 33 | R17: 12 | S17: =SUM(K17:L17,Q17:R17) -> 45 | U17: 10 | V17: Акунова Ч. | W17: Инф контроль | X17: =SUMIF($B$8:$B$591,$V17,G$8:G$591) -> 54 | Y17: =SUMIF($B$8:$B$591,$V17,M$8:M$591) -> 0 | Z17: =SUM(X17:Y17) -> 54 | AB17: =COUNTIF(V$8:V$85,V17) -> 1
B18: Дикамбаев М. ВНЕШ | G18: =SUM(K19:L21) -> 0 | M18: =SUM(Q19:R21) -> 18 | S18: =SUM(G18:Q18) -> 18 | U18: 11 | V18: Акунова Ч. ВНЕШТ | W18: Хирургия | X18: =SUMIF($B$8:$B$591,$V18,G$8:G$591) -> 0 | Y18: =SUMIF($B$8:$B$591,$V18,M$8:M$591) -> 109 | Z18: =SUM(X18:Y18) -> 109 | AB18: =COUNTIF(V$8:V$85,V18) -> 1
C19: 1 | D19: СД-21 | E19: 20 | F19: =IF(E19<15,1,IF(((E19>=15)*(E19<23)),2,3)) -> 2 | I19: =G19 -> 0 | J19: =IF(H19=0,0,H19*$F19) -> 0 | K19: =SUM(I19:J19) -> 0 | M19: 6 | O19: =M19 -> 6 | P19: =IF(N19=0,0,N19*$F19) -> 0 | Q19: =SUM(O19:P19) -> 6 | S19: =SUM(K19:L19,Q19:R19) -> 6 | U19: 12 | V19: Алиева Х.О. | W19: Оториноларингология | X19: =SUMIF($B$8:$B$591,$V19,G$8:G$591) -> 90 | Y19: =SUMIF($B$8:$B$591,$V19,M$8:M$591) -> 225 | Z19: =SUM(X19:Y19) -> 315 | AB19: =COUNTIF(V$8:V$85,V19) -> 1
C20: 4 | D20: ЛД-31 | E20: 25 | F20: =IF(E20<15,1,IF(((E20>=15)*(E20<23)),2,3)) -> 3 | I20: =G20 -> 0 | J20: =IF(H20=0,0,H20*$F20) -> 0 | K20: =SUM(I20:J20) -> 0 | M20: 6 | O20: =M20 -> 6 | P20: =IF(N20=0,0,N20*$F20) -> 0 | Q20: =SUM(O20:P20) -> 6 | S20: =SUM(K20:L20,Q20:R20) -> 6 | U20: 13 | V20: Аманатова А. | W20: Анг язык | X20: =SUMIF($B$8:$B$591,$V20,G$8:G$591) -> 156 | Y20: =SUMIF($B$8:$B$591,$V20,M$8:M$591) -> 42 | Z20: =SUM(X20:Y20) -> 198 | AB20: =COUNTIF(V$8:V$85,V20) -> 1
C21: 6 | D21: ЛД-21 | E21: 25 | F21: =IF(E21<15,1,IF(((E21>=15)*(E21<23)),2,3)) -> 3 | I21: =G21 -> 0 | J21: =IF(H21=0,0,H21*$F21) -> 0 | K21: =SUM(I21:J21) -> 0 | M21: 6 | O21: =M21 -> 6 | P21: =IF(N21=0,0,N21*$F21) -> 0 | Q21: =SUM(O21:P21) -> 6 | S21: =SUM(K21:L21,Q21:R21) -> 6 | U21: 14 | V21: Аманкелдиева А. | W21: Терапия | X21: =SUMIF($B$8:$B$591,$V21,G$8:G$591) -> 81 | Y21: =SUMIF($B$8:$B$591,$V21,M$8:M$591) -> 81 | Z21: =SUM(X21:Y21) -> 162 | AB21: =COUNTIF(V$8:V$85,V21) -> 1
B22: Дикамбаев М. | G22: =SUM(K23:L24) -> 0 | M22: =SUM(Q23:R24) -> 177 | S22: =SUM(G22:Q22) -> 177 | U22: 15 | V22: Асаналиева Г. | W22: Мед массаж | X22: =SUMIF($B$8:$B$591,$V22,G$8:G$591) -> 0 | Y22: =SUMIF($B$8:$B$591,$V22,M$8:M$591) -> 111 | Z22: =SUM(X22:Y22) -> 111 | AB22: =COUNTIF(V$8:V$85,V22) -> 1
C23: 2 | D23: СД-21 | E23: 20 | F23: =IF(E23<15,1,IF(((E23>=15)*(E23<23)),2,3)) -> 2 | I23: =G23 -> 0 | J23: =IF(H23=0,0,H23*$F23) -> 0 | K23: =SUM(I23:J23) -> 0 | N23: 36 | O23: =M23 -> 0 | P23: =IF(N23=0,0,N23*$F23) -> 72 | Q23: =SUM(O23:P23) -> 72 | R23: 12 | S23: =SUM(K23:L23,Q23:R23) -> 84 | U23: 16 | V23: Аскарбеков Б. | W23: БЖМК | X23: =SUMIF($B$8:$B$591,$V23,G$8:G$591) -> 0 | Y23: =SUMIF($B$8:$B$591,$V23,M$8:M$591) -> 66 | Z23: =SUM(X23:Y23) -> 66 | AB23: =COUNTIF(V$8:V$85,V23) -> 1
C24: 1 | D24: ЛД-21 | E24: 25 | F24: =IF(E24<15,1,IF(((E24>=15)*(E24<23)),2,3)) -> 3 | I24: =G24 -> 0 | J24: =IF(H24=0,0,H24*$F24) -> 0 | K24: =SUM(I24:J24) -> 0 | N24: 27 | O24: =M24 -> 0 | P24: =IF(N24=0,0,N24*$F24) -> 81 | Q24: =SUM(O24:P24) -> 81 | R24: 12 | S24: =SUM(K24:L24,Q24:R24) -> 93 | U24: 17 | V24: Аширахманова Г.Б. | W24: Педиатрия | X24: =SUMIF($B$8:$B$591,$V24,G$8:G$591) -> 66 | Y24: =SUMIF($B$8:$B$591,$V24,M$8:M$591) -> 162 | Z24: =SUM(X24:Y24) -> 228 | AB24: =COUNTIF(V$8:V$85,V24) -> 1
B25: Янхаева З. | G25: =SUM(K26:L26) -> 120 | M25: =SUM(Q26:R26) -> 0 | S25: =SUM(G25:Q25) -> 120 | U25: 18 | V25: Бейсенбиева А. | W25: Терапия | X25: =SUMIF($B$8:$B$591,$V25,G$8:G$591) -> 297 | Y25: =SUMIF($B$8:$B$591,$V25,M$8:M$591) -> 252 | Z25: =SUM(X25:Y25) -> 549 | AB25: =COUNTIF(V$8:V$85,V25) -> 1
C26: 2 | D26: ЛД-41 | E26: 25 | F26: =IF(E26<15,1,IF(((E26>=15)*(E26<23)),2,3)) -> 3 | H26: 36 | I26: =G26 -> 0 | J26: =IF(H26=0,0,H26*$F26) -> 108 | K26: =SUM(I26:J26) -> 108 | L26: 12 | O26: =M26 -> 0 | P26: =IF(N26=0,0,N26*$F26) -> 0 | Q26: =SUM(O26:P26) -> 0 | S26: =SUM(K26:L26,Q26:R26) -> 120 | U26: 19 | V26: Бектурганова Н.Н. | W26: Мед массаж | X26: =SUMIF($B$8:$B$591,$V26,G$8:G$591) -> 0 | Y26: =SUMIF($B$8:$B$591,$V26,M$8:M$591) -> 0 | Z26: =SUM(X26:Y26) -> 0 | AB26: =COUNTIF(V$8:V$85,V26) -> 1
B27: Кучерова В. | G27: =SUM(K28:L29) -> 231 | M27: =SUM(Q28:R29) -> 204 | S27: =SUM(G27:Q27) -> 435 | U27: 20 | V27: Гениевская Н. | W27: Инфекционные болезни | X27: =SUMIF($B$8:$B$591,$V27,G$8:G$591) -> 240 | Y27: =SUMIF($B$8:$B$591,$V27,M$8:M$591) -> 207 | Z27: =SUM(X27:Y27) -> 447 | AB27: =COUNTIF(V$8:V$85,V27) -> 1
C28: 3 | D28: СД-31 | E28: 25 | F28: =IF(E28<15,1,IF(((E28>=15)*(E28<23)),2,3)) -> 3 | H28: 33 | J28: =IF(H28=0,0,H28*$F28) -> 99 | K28: =SUM(I28:J28) -> 99 | L28: 12 | N28: 33 | P28: =IF(N28=0,0,N28*$F28) -> 99 | Q28: =SUM(O28:P28) -> 99 | R28: 12 | S28: =SUM(K28:L28,Q28:R28) -> 222 | U28: 21 | V28: Герасимчук А. | W28: ГиГТ | X28: =SUMIF($B$8:$B$591,$V28,G$8:G$591) -> 333 | Y28: =SUMIF($B$8:$B$591,$V28,M$8:M$591) -> 445 | Z28: =SUM(X28:Y28) -> 778 | AB28: =COUNTIF(V$8:V$85,V28) -> 1
C29: 3 | D29: ЛД-31 | E29: 25 | F29: 3 | H29: 36 | J29: =IF(H29=0,0,H29*$F29) -> 108 | K29: =SUM(I29:J29) -> 108 | L29: 12 | N29: 27 | P29: =IF(N29=0,0,N29*$F29) -> 81 | Q29: =SUM(O29:P29) -> 81 | R29: 12 | S29: =SUM(K29:L29,Q29:R29) -> 213 | U29: 22 | V29: Дженбекова А. | W29: ПОПД | X29: =SUMIF($B$8:$B$591,$V29,G$8:G$591) -> 118 | Y29: =SUMIF($B$8:$B$591,$V29,M$8:M$591) -> 189 | Z29: =SUM(X29:Y29) -> 307 | AB29: =COUNTIF(V$8:V$85,V29) -> 1
B30: 2 | D30: Терапия | G30: =SUM(G31,G33,G40,G46) -> 609 | M30: =SUM(M31,M33,M40,M46) -> 564 | S30: =SUM(S31,S33,S40,S46) -> 1173 | U30: 23 | V30: Джолдошева Д.Э. | W30: Акушерство | X30: =SUMIF($B$8:$B$591,$V30,G$8:G$591) -> 117 | Y30: =SUMIF($B$8:$B$591,$V30,M$8:M$591) -> 81 | Z30: =SUM(X30:Y30) -> 198 | AB30: =COUNTIF(V$8:V$85,V30) -> 1
B31: Аманкелдиева А. | G31: =SUM(K32:L32) -> 81 | M31: =SUM(Q32:R32) -> 81 | S31: =SUM(G31:Q31) -> 162 | U31: 24 | V31: Дикамбаев М. | W31: Хирургитя | X31: =SUMIF($B$8:$B$591,$V31,G$8:G$591) -> 0 | Y31: =SUMIF($B$8:$B$591,$V31,M$8:M$591) -> 177 | Z31: =SUM(X31:Y31) -> 177 | AB31: =COUNTIF(V$8:V$85,V31) -> 1
C32: 3 | D32: ЛД-31 | E32: 25 | F32: =IF(E32<15,1,IF(((E32>=15)*(E32<23)),2,3)) -> 3 | H32: 27 | I32: =G32 -> 0 | J32: =IF(H32=0,0,H32*$F32) -> 81 | K32: =SUM(I32:J32) -> 81 | N32: 27 | O32: =M32 -> 0 | P32: =IF(N32=0,0,N32*$F32) -> 81 | Q32: =SUM(O32:P32) -> 81 | S32: =SUM(K32:L32,Q32:R32) -> 162 | U32: 25 | V32: Дикамбаев М. ВНЕШ | W32: Хирургия | X32: =SUMIF($B$8:$B$591,$V32,G$8:G$591) -> 0 | Y32: =SUMIF($B$8:$B$591,$V32,M$8:M$591) -> 18 | Z32: =SUM(X32:Y32) -> 18 | AB32: =COUNTIF(V$8:V$85,V32) -> 1
B33: Янхаева З. | G33: =SUM(K34:L39) -> 231 | M33: =SUM(Q34:R39) -> 0 | S33: =SUM(G33:Q33) -> 231 | U33: 26 | V33: Жакыпбеков К.Ш. | W33: Хирургия | X33: =SUMIF($B$8:$B$591,$V33,G$8:G$591) -> 222 | Y33: =SUMIF($B$8:$B$591,$V33,M$8:M$591) -> 66 | Z33: =SUM(X33:Y33) -> 288 | AB33: =COUNTIF(V$8:V$85,V33) -> 1
C34: 1 | D34: СД-21 | E34: 20 | F34: =IF(E34<15,1,IF(((E34>=15)*(E34<23)),2,3)) -> 2 | I34: =G34 -> 0 | J34: =IF(H34=0,0,H34*$F34) -> 0 | K34: =SUM(I34:J34) -> 0 | O34: =M34 -> 0 | P34: =IF(N34=0,0,N34*$F34) -> 0 | Q34: =SUM(O34:P34) -> 0 | S34: =SUM(K34:L34,Q34:R34) -> 0 | U34: 27 | V34: Желденбаева Г. | W34: Кырг язык | X34: =SUMIF($B$8:$B$591,$V34,G$8:G$591) -> 104 | Y34: =SUMIF($B$8:$B$591,$V34,M$8:M$591) -> 0 | Z34: =SUM(X34:Y34) -> 104 | AB34: =COUNTIF(V$8:V$85,V34) -> 1
C35: 2 | D35: АД-21 | E35: 13 | F35: =IF(E35<15,1,IF(((E35>=15)*(E35<23)),2,3)) -> 1 | G35: 18 | I35: =G35 -> 18 | J35: =IF(H35=0,0,H35*$F35) -> 0 | K35: =SUM(I35:J35) -> 18 | O35: =M35 -> 0 | P35: =IF(N35=0,0,N35*$F35) -> 0 | Q35: =SUM(O35:P35) -> 0 | S35: =SUM(K35:L35,Q35:R35) -> 18 | U35: 28 | V35: Жидебаева Н.Т. | W35: ОСД | X35: =SUMIF($B$8:$B$591,$V35,G$8:G$591) -> 278 | Y35: =SUMIF($B$8:$B$591,$V35,M$8:M$591) -> 291 | Z35: =SUM(X35:Y35) -> 569 | AB35: =COUNTIF(V$8:V$85,V35) -> 1
C36: 3 | D36: СД-31 | E36: 25 | F36: =IF(E36<15,1,IF(((E36>=15)*(E36<23)),2,3)) -> 3 | G36: 12 | I36: =G36 -> 12 | J36: =IF(H36=0,0,H36*$F36) -> 0 | K36: =SUM(I36:J36) -> 12 | O36: =M36 -> 0 | P36: =IF(N36=0,0,N36*$F36) -> 0 | Q36: =SUM(O36:P36) -> 0 | S36: =SUM(K36:L36,Q36:R36) -> 12 | U36: 29 | V36: Замирбекова К. | W36: ПМП | X36: =SUMIF($B$8:$B$591,$V36,G$8:G$591) -> 225 | Y36: =SUMIF($B$8:$B$591,$V36,M$8:M$591) -> 102 | Z36: =SUM(X36:Y36) -> 327 | AB36: =COUNTIF(V$8:V$85,V36) -> 1
C37: 4 | D37: ЛД-31 | E37: 25 | F37: =IF(E37<15,1,IF(((E37>=15)*(E37<23)),2,3)) -> 3 | G37: 18 | I37: =G37 -> 18 | J37: =IF(H37=0,0,H37*$F37) -> 0 | K37: =SUM(I37:J37) -> 18 | O37: =M37 -> 0 | P37: =IF(N37=0,0,N37*$F37) -> 0 | Q37: =SUM(O37:P37) -> 0 | S37: =SUM(K37:L37,Q37:R37) -> 18 | U37: 30 | V37: Иманалиева А. | W37: ПОПД | X37: =SUMIF($B$8:$B$591,$V37,G$8:G$591) -> 8 | Y37: =SUMIF($B$8:$B$591,$V37,M$8:M$591) -> 0 | Z37: =SUM(X37:Y37) -> 8 | AB37: =COUNTIF(V$8:V$85,V37) -> 1
C38: 5 | D38: ЛД-41 | E38: 25 | F38: =IF(E38<15,1,IF(((E38>=15)*(E38<23)),2,3)) -> 3 | G38: 18 | I38: =G38 -> 18 | J38: =IF(H38=0,0,H38*$F38) -> 0 | K38: =SUM(I38:J38) -> 18 | O38: =M38 -> 0 | P38: =IF(N38=0,0,N38*$F38) -> 0 | Q38: =SUM(O38:P38) -> 0 | S38: =SUM(K38:L38,Q38:R38) -> 18 | U38: 31 | V38: Исалиева Г.Б. | W38: Манасоведение | X38: =SUMIF($B$8:$B$591,$V38,G$8:G$591) -> 150 | Y38: =SUMIF($B$8:$B$591,$V38,M$8:M$591) -> 0 | Z38: =SUM(X38:Y38) -> 150 | AB38: =COUNTIF(V$8:V$85,V38) -> 1
C39: 6 | D39: ЛД-21 | E39: 25 | F39: =IF(E39<15,1,IF(((E39>=15)*(E39<23)),2,3)) -> 3 | G39: 36 | H39: 39 | I39: =G39 -> 36 | J39: =IF(H39=0,0,H39*$F39) -> 117 | K39: =SUM(I39:J39) -> 153 | L39: 12 | O39: =M39 -> 0 | P39: =IF(N39=0,0,N39*$F39) -> 0 | Q39: =SUM(O39:P39) -> 0 | S39: =SUM(K39:L39,Q39:R39) -> 165 | U39: 32 | V39: Исмаилова З.Д. | W39: Болезни зубов и полости рта | X39: =SUMIF($B$8:$B$591,$V39,G$8:G$591) -> 128 | Y39: =SUMIF($B$8:$B$591,$V39,M$8:M$591) -> 123 | Z39: =SUM(X39:Y39) -> 251 | AB39: =COUNTIF(V$8:V$85,V39) -> 1
B40: Омуркул к. К. | G40: =SUM(K41:L45) -> 0 | M40: =SUM(Q41:R45) -> 231 | S40: =SUM(G40:Q40) -> 231 | U40: 33 | V40: Кадыракун у. К. | W40: История | X40: =SUMIF($B$8:$B$591,$V40,G$8:G$591) -> 108 | Y40: =SUMIF($B$8:$B$591,$V40,M$8:M$591) -> 96 | Z40: =SUM(X40:Y40) -> 204 | AB40: =COUNTIF(V$8:V$85,V40) -> 1
C41: 1 | D41: СД-21 | E41: 20 | F41: =IF(E41<15,1,IF(((E41>=15)*(E41<23)),2,3)) -> 2 | I41: =G41 -> 0 | J41: =IF(H41=0,0,H41*$F41) -> 0 | K41: =SUM(I41:J41) -> 0 | M41: 24 | O41: =M41 -> 24 | P41: =IF(N41=0,0,N41*$F41) -> 0 | Q41: =SUM(O41:P41) -> 24 | S41: =SUM(K41:L41,Q41:R41) -> 24 | U41: 34 | V41: Карыбаев Т. | W41: Реаниматология | X41: =SUMIF($B$8:$B$591,$V41,G$8:G$591) -> 99 | Y41: =SUMIF($B$8:$B$591,$V41,M$8:M$591) -> 0 | Z41: =SUM(X41:Y41) -> 99 | AB41: =COUNTIF(V$8:V$85,V41) -> 1
C42: 2 | D42: АД-21 | E42: 13 | F42: =IF(E42<15,1,IF(((E42>=15)*(E42<23)),2,3)) -> 1 | I42: =G42 -> 0 | J42: =IF(H42=0,0,H42*$F42) -> 0 | K42: =SUM(I42:J42) -> 0 | M42: 12 | O42: =M42 -> 12 | P42: =IF(N42=0,0,N42*$F42) -> 0 | Q42: =SUM(O42:P42) -> 12 | S42: =SUM(K42:L42,Q42:R42) -> 12 | U42: 35 | V42: Карыбаева М. | W42: ОСД | X42: =SUMIF($B$8:$B$591,$V42,G$8:G$591) -> 114 | Y42: =SUMIF($B$8:$B$591,$V42,M$8:M$591) -> 0 | Z42: =SUM(X42:Y42) -> 114 | AB42: =COUNTIF(V$8:V$85,V42) -> 1
...

Sheet Контракт
B2: Годовая нагрузка преподавателей | U2: Годовая нагрузка преподавателей
B3: на 2025-2026 учебный год (контракт) | U3: на 2025-2026 учебный год (контракт)
B5: Ф.И.О. | D5: Группа | E5: Кол-во ст. | F5: Подг | G5: Нагрузка | I5: Кол-во часов I полугодие | M5: Нагрузка | O5: Кол-во часов II полугодие | S5: Всего за учебный год | U5: № | V5: Ф.И.О. | W5: Предмет | X5: Количество часов
G6: Лек. | H6: Практ., семин., лаб. | I6: Лек. | J6: Практ., семин., лаб. | K6: Итого | L6: Тест | M6: Лек. | N6: Практ., семин., лаб. | O6: Лек. | P6: Практ., семин., лаб. | Q6: Итого | R6: Тест | X6: Итого за I полугоде | Y6: Итого за II полугоде | Z6: Всего за учебный год
B7: № | G7: I полугодие | M7: II полугодие | AB7: Кол-во
B8: 1 | D8: Хирургия | G8: =SUM(G9,G18,G22,G24,G27,G34) -> 657 | M8: =SUM(M9,M18,M22,M24,M27,M34) -> 795 | S8: =SUM(S9,S18,S22,S24,S27,S34) -> 1452 | U8: 1 | V8: Абдиева Ж. | W8: ОСД | X8: =SUMIF($B$9:$B$884,$V8,G$9:G$884) -> 40 | Y8: =SUMIF($B$9:$B$884,$V8,M$9:M$884) -> 42 | Z8: =SUM(X8:Y8) -> 82 | AB8: =COUNTIF(V$8:V$99,V8) -> 1
B9: Жакыпбеков К.Ш. | G9: =SUM(K10:L17) -> 297 | M9: =SUM(Q10:R17) -> 54 | S9: =SUM(G9:Q9) -> 351 | U9: 2 | V9: Абдрахманова Ж. | W9: Инф контроль | X9: =SUMIF($B$9:$B$884,$V9,G$9:G$884) -> 84 | Y9: =SUMIF($B$9:$B$884,$V9,M$9:M$884) -> 0 | Z9: =SUM(X9:Y9) -> 84 | AB9: =COUNTIF(V$8:V$99,V9) -> 1
C10: 1 | D10: КСД-21 | E10: 24 | F10: =IF(E10<15,1,IF(((E10>=15)*(E10<23)),2,3)) -> 3 | I10: =G10 -> 0 | J10: =IF(H10=0,0,H10*$F10) -> 0 | K10: =SUM(I10:J10) -> 0 | M10: 18 | O10: =M10 -> 18 | P10: =IF(N10=0,0,N10*$F10) -> 0 | Q10: =SUM(O10:P10) -> 18 | S10: =SUM(K10:L10,Q10:R10) -> 18 | U10: 3 | V10: Абдуллаева М.Н. | W10: Инф контроль | X10: =SUMIF($B$9:$B$884,$V10,G$9:G$884) -> 24 | Y10: =SUMIF($B$9:$B$884,$V10,M$9:M$884) -> 66 | Z10: =SUM(X10:Y10) -> 90 | AB10: =COUNTIF(V$8:V$99,V10) -> 1
C11: 2 | D11: КСД-31 | E11: 23 | F11: =IF(E11<15,1,IF(((E11>=15)*(E11<23)),2,3)) -> 3 | G11: 12 | H11: 33 | I11: =G11 -> 12 | J11: =IF(H11=0,0,H11*$F11) -> 99 | K11: =SUM(I11:J11) -> 111 | L11: 12 | O11: =M11 -> 0 | P11: =IF(N11=0,0,N11*$F11) -> 0 | Q11: =SUM(O11:P11) -> 0 | S11: =SUM(K11:L11,Q11:R11) -> 123 | U11: 4 | V11: Абдуллаева М.Н. ШТ | W11: ОСД | X11: =SUMIF($B$9:$B$884,$V11,G$9:G$884) -> 150 | Y11: =SUMIF($B$9:$B$884,$V11,M$9:M$884) -> 30 | Z11: =SUM(X11:Y11) -> 180 | AB11: =COUNTIF(V$8:V$99,V11) -> 1
C12: 2 | D12: КСД-31 | E12: 19 | F12: =IF(E12<15,1,IF(((E12>=15)*(E12<23)),2,3)) -> 2 | I12: =G12 -> 0 | J12: =IF(H12=0,0,H12*$F12) -> 0 | K12: =SUM(I12:J12) -> 0 | M12: 12 | O12: =M12 -> 12 | P12: =IF(N12=0,0,N12*$F12) -> 0 | Q12: =SUM(O12:P12) -> 12 | S12: =SUM(K12:L12,Q12:R12) -> 12 | U12: 5 | V12: Абдыкеримова А.Н. | W12: Фрам химия | X12: =SUMIF($B$9:$B$884,$V12,G$9:G$884) -> 30 | Y12: =SUMIF($B$9:$B$884,$V12,M$9:M$884) -> 400 | Z12: =SUM(X12:Y12) -> 430 | AB12: =COUNTIF(V$8:V$99,V12) -> 1
C13: 2 | D13: КСД-32 | E13: 20 | F13: =IF(E13<15,1,IF(((E13>=15)*(E13<23)),2,3)) -> 2 | H13: 33 | I13: =G13 -> 0 | J13: =IF(H13=0,0,H13*$F13) -> 66 | K13: =SUM(I13:J13) -> 66 | L13: 12 | O13: =M13 -> 0 | P13: =IF(N13=0,0,N13*$F13) -> 0 | Q13: =SUM(O13:P13) -> 0 | S13: =SUM(K13:L13,Q13:R13) -> 78 | U13: 6 | V13: Абдыкеримова К. | W13: Основы реабилитации (физиотерапия) | X13: =SUMIF($B$9:$B$884,$V13,G$9:G$884) -> 303 | Y13: =SUMIF($B$9:$B$884,$V13,M$9:M$884) -> 0 | Z13: =SUM(X13:Y13) -> 303 | AB13: =COUNTIF(V$8:V$99,V13) -> 1
C14: 3 | D14: КЛД-31 | E14: 27 | F14: =IF(E14<15,1,IF(((E14>=15)*(E14<23)),2,3)) -> 3 | G14: 24 | I14: =G14 -> 24 | J14: =IF(H14=0,0,H14*$F14) -> 0 | K14: =SUM(I14:J14) -> 24 | M14: 12 | O14: =M14 -> 12 | P14: =IF(N14=0,0,N14*$F14) -> 0 | Q14: =SUM(O14:P14) -> 12 | S14: =SUM(K14:L14,Q14:R14) -> 36 | U14: 7 | V14: Азизова Н. | W14: СМ | X14: =SUMIF($B$9:$B$884,$V14,G$9:G$884) -> 312 | Y14: =SUMIF($B$9:$B$884,$V14,M$9:M$884) -> 369 | Z14: =SUM(X14:Y14) -> 681 | AB14: =COUNTIF(V$8:V$99,V14) -> 1
C15: 4 | D15: КЛД-41 | E15: 29 | F15: =IF(E15<15,1,IF(((E15>=15)*(E15<23)),2,3)) -> 3 | G15: 18 | I15: =G15 -> 18 | J15: =IF(H15=0,0,H15*$F15) -> 0 | K15: =SUM(I15:J15) -> 18 | O15: =M15 -> 0 | P15: =IF(N15=0,0,N15*$F15) -> 0 | Q15: =SUM(O15:P15) -> 0 | S15: =SUM(K15:L15,Q15:R15) -> 18 | U15: 8 | V15: Айбашева А. | W15: СМ | X15: =SUMIF($B$9:$B$884,$V15,G$9:G$884) -> 120 | Y15: =SUMIF($B$9:$B$884,$V15,M$9:M$884) -> 0 | Z15: =SUM(X15:Y15) -> 120 | AB15: =COUNTIF(V$8:V$99,V15) -> 1
C16: 5 | D16: КЛД-21 | E16: 17 | F16: 1 | I16: =G16 -> 0 | J16: =IF(H16=0,0,H16*$F16) -> 0 | K16: =SUM(I16:J16) -> 0 | M16: 12 | O16: =M16 -> 12 | P16: =IF(N16=0,0,N16*$F16) -> 0 | Q16: =SUM(O16:P16) -> 12 | S16: =SUM(K16:L16,Q16:R16) -> 12 | U16: 9 | V16: Акимканова А. | W16: ОСД | X16: =SUMIF($B$9:$B$884,$V16,G$9:G$884) -> 30 | Y16: =SUMIF($B$9:$B$884,$V16,M$9:M$884) -> 0 | Z16: =SUM(X16:Y16) -> 30 | AB16: =COUNTIF(V$8:V$99,V16) -> 1
C17: 1 | D17: КАД-21 | E17: 7 | F17: =IF(E17<15,1,IF(((E17>=15)*(E17<23)),2,3)) -> 1 | H17: 42 | I17: =G17 -> 0 | J17: =IF(H17=0,0,H17*$F17) -> 42 | K17: =SUM(I17:J17) -> 42 | L17: 12 | O17: =M17 -> 0 | P17: =IF(N17=0,0,N17*$F17) -> 0 | Q17: =SUM(O17:P17) -> 0 | S17: =SUM(K17:L17,Q17:R17) -> 54 | U17: 10 | V17: Акматов У.О. | W17: Зуботех матер | X17: =SUMIF($B$9:$B$884,$V17,G$9:G$884) -> 554 | Y17: =SUMIF($B$9:$B$884,$V17,M$9:M$884) -> 468 | Z17: =SUM(X17:Y17) -> 1022 | AB17: =COUNTIF(V$8:V$99,V17) -> 1
B18: Акунова Ч. ВНЕШТ | G18: =SUM(K19:L21) -> 0 | M18: =SUM(Q19:R21) -> 156 | S18: =SUM(G18:Q18) -> 156 | U18: 11 | V18: Акматова Ж. | W18: Гинекология | X18: =SUMIF($B$9:$B$884,$V18,G$9:G$884) -> 33 | Y18: =SUMIF($B$9:$B$884,$V18,M$9:M$884) -> 0 | Z18: =SUM(X18:Y18) -> 33 | AB18: =COUNTIF(V$8:V$99,V18) -> 1
C19: 1 | D19: КАД-21 | E19: 7 | F19: =IF(E19<15,1,IF(((E19>=15)*(E19<23)),2,3)) -> 1 | I19: =G19 -> 0 | J19: =IF(H19=0,0,H19*$F19) -> 0 | K19: =SUM(I19:J19) -> 0 | N19: 33 | O19: =M19 -> 0 | P19: =IF(N19=0,0,N19*$F19) -> 33 | Q19: =SUM(O19:P19) -> 33 | R19: 12 | S19: =SUM(K19:L19,Q19:R19) -> 45 | U19: 12 | V19: Акунова Ч. | W19: Инф контроль | X19: =SUMIF($B$9:$B$884,$V19,G$9:G$884) -> 89 | Y19: =SUMIF($B$9:$B$884,$V19,M$9:M$884) -> 0 | Z19: =SUM(X19:Y19) -> 89 | AB19: =COUNTIF(V$8:V$99,V19) -> 1
C20: 3 | D20: КЛД-21 | E20: 17 | F20: 1 | I20: =G20 -> 0 | J20: =IF(H20=0,0,H20*$F20) -> 0 | K20: =SUM(I20:J20) -> 0 | N20: 27 | O20: =M20 -> 0 | P20: =IF(N20=0,0,N20*$F20) -> 27 | Q20: =SUM(O20:P20) -> 27 | R20: 6 | S20: =SUM(K20:L20,Q20:R20) -> 33 | U20: 13 | V20: Акунова Ч. ВНЕШТ | W20: ОСД | X20: =SUMIF($B$9:$B$884,$V20,G$9:G$884) -> 0 | Y20: =SUMIF($B$9:$B$884,$V20,M$9:M$884) -> 156 | Z20: =SUM(X20:Y20) -> 156 | AB20: =COUNTIF(V$8:V$99,V20) -> 1
C21: 2 | D21: КСД-32 | E21: 20 | F21: =IF(E21<15,1,IF(((E21>=15)*(E21<23)),2,3)) -> 2 | I21: =G21 -> 0 | J21: =IF(H21=0,0,H21*$F21) -> 0 | K21: =SUM(I21:J21) -> 0 | N21: 33 | O21: =M21 -> 0 | P21: =IF(N21=0,0,N21*$F21) -> 66 | Q21: =SUM(O21:P21) -> 66 | R21: 12 | S21: =SUM(K21:L21,Q21:R21) -> 78 | U21: 14 | V21: Алиева Х.О. | W21: Офтальмология | X21: =SUMIF($B$9:$B$884,$V21,G$9:G$884) -> 288 | Y21: =SUMIF($B$9:$B$884,$V21,M$9:M$884) -> 477 | Z21: =SUM(X21:Y21) -> 765 | AB21: =COUNTIF(V$8:V$99,V21) -> 1
B22: Янхаева З. | G22: =SUM(K23:L23) -> 120 | M22: =SUM(Q23:R23) -> 0 | S22: =SUM(G22:Q22) -> 120 | U22: 15 | V22: Аманатова А. | W22: Анг. Язык | X22: =SUMIF($B$9:$B$884,$V22,G$9:G$884) -> 408 | Y22: =SUMIF($B$9:$B$884,$V22,M$9:M$884) -> 374 | Z22: =SUM(X22:Y22) -> 782 | AB22: =COUNTIF(V$8:V$99,V22) -> 1
C23: 1 | D23: КЛД-41 | E23: 29 | F23: =IF(E23<15,1,IF(((E23>=15)*(E23<23)),2,3)) -> 3 | H23: 36 | I23: =G23 -> 0 | J23: =IF(H23=0,0,H23*$F23) -> 108 | K23: =SUM(I23:J23) -> 108 | L23: 12 | O23: =M23 -> 0 | P23: =IF(N23=0,0,N23*$F23) -> 0 | Q23: =SUM(O23:P23) -> 0 | S23: =SUM(K23:L23,Q23:R23) -> 120 | U23: 16 | V23: Аманкелдиева А. | W23: Терапия | X23: =SUMIF($B$9:$B$884,$V23,G$9:G$884) -> 93 | Y23: =SUMIF($B$9:$B$884,$V23,M$9:M$884) -> 93 | Z23: =SUM(X23:Y23) -> 186 | AB23: =COUNTIF(V$8:V$99,V23) -> 1
B24: Замирбекова К. | G24: =SUM(K25:L26) -> 0 | M24: =SUM(Q25:R26) -> 18 | S24: =SUM(G24:Q24) -> 18 | U24: 17 | V24: Андосова Э. | W24: ОСД | X24: =SUMIF($B$9:$B$884,$V24,G$9:G$884) -> 4 | Y24: =SUMIF($B$9:$B$884,$V24,M$9:M$884) -> 0 | Z24: =SUM(X24:Y24) -> 4 | AB24: =COUNTIF(V$8:V$99,V24) -> 1
C25: 3 | D25: КЛД-22 | E25: 18 | F25: =IF(E25<15,1,IF(((E25>=15)*(E25<23)),2,3)) -> 2 | I25: =G25 -> 0 | J25: =IF(H25=0,0,H25*$F25) -> 0 | K25: =SUM(I25:J25) -> 0 | O25: =M25 -> 0 | P25: =IF(N25=0,0,N25*$F25) -> 0 | Q25: =SUM(O25:P25) -> 0 | R25: 12 | S25: =SUM(K25:L25,Q25:R25) -> 12 | U25: 18 | V25: Асаналиева Г. | X25: =SUMIF($B$9:$B$884,$V25,G$9:G$884) -> 0 | Y25: =SUMIF($B$9:$B$884,$V25,M$9:M$884) -> 168 | Z25: =SUM(X25:Y25) -> 168 | AB25: =COUNTIF(V$8:V$99,V25) -> 1
C26: 3 | D26: КЛД-21 | E26: 17 | F26: 1 | I26: =G26 -> 0 | J26: =IF(H26=0,0,H26*$F26) -> 0 | K26: =SUM(I26:J26) -> 0 | O26: =M26 -> 0 | P26: =IF(N26=0,0,N26*$F26) -> 0 | Q26: =SUM(O26:P26) -> 0 | R26: 6 | S26: =SUM(K26:L26,Q26:R26) -> 6 | U26: 19 | V26: Аскарбеков Б. | W26: НВМП | X26: =SUMIF($B$9:$B$884,$V26,G$9:G$884) -> 66 | Y26: =SUMIF($B$9:$B$884,$V26,M$9:M$884) -> 145 | Z26: =SUM(X26:Y26) -> 211 | AB26: =COUNTIF(V$8:V$99,V26) -> 1
B27: Дикамбаев М. | G27: =SUM(K28:L33) -> 0 | M27: =SUM(Q28:R33) -> 381 | S27: =SUM(G27:Q27) -> 381 | U27: 20 | V27: Асылбекова А. | W27: Акушерство | X27: =SUMIF($B$9:$B$884,$V27,G$9:G$884) -> 153 | Y27: =SUMIF($B$9:$B$884,$V27,M$9:M$884) -> 0 | Z27: =SUM(X27:Y27) -> 153 | AB27: =COUNTIF(V$8:V$99,V27) -> 1
C28: 2 | D28: КСД-31 | E28: 19 | F28: =IF(E28<15,1,IF(((E28>=15)*(E28<23)),2,3)) -> 2 | I28: =G28 -> 0 | J28: =IF(H28=0,0,H28*$F28) -> 0 | K28: =SUM(I28:J28) -> 0 | N28: 33 | O28: =M28 -> 0 | P28: =IF(N28=0,0,N28*$F28) -> 66 | Q28: =SUM(O28:P28) -> 66 | R28: 12 | S28: =SUM(K28:L28,Q28:R28) -> 78 | U28: 21 | V28: Аширахманова Г.Б. | W28: Педиатрия | X28: =SUMIF($B$9:$B$884,$V28,G$9:G$884) -> 54 | Y28: =SUMIF($B$9:$B$884,$V28,M$9:M$884) -> 78 | Z28: =SUM(X28:Y28) -> 132 | AB28: =COUNTIF(V$8:V$99,V28) -> 1
C29: 3 | D29: КЛД-31 | E29: 27 | F29: =IF(E29<15,1,IF(((E29>=15)*(E29<23)),2,3)) -> 3 | I29: =G29 -> 0 | J29: =IF(H29=0,0,H29*$F29) -> 0 | K29: =SUM(I29:J29) -> 0 | M29: 6 | O29: =M29 -> 6 | P29: =IF(N29=0,0,N29*$F29) -> 0 | Q29: =SUM(O29:P29) -> 6 | S29: =SUM(K29:L29,Q29:R29) -> 6 | U29: 22 | V29: Бейсенбиева А. | W29: Терапия | X29: =SUMIF($B$9:$B$884,$V29,G$9:G$884) -> 204 | Y29: =SUMIF($B$9:$B$884,$V29,M$9:M$884) -> 327 | Z29: =SUM(X29:Y29) -> 531 | AB29: =COUNTIF(V$8:V$99,V29) -> 1
C30: 3 | D30: КЛД-22 | E30: 18 | F30: =IF(E30<15,1,IF(((E30>=15)*(E30<23)),2,3)) -> 2 | I30: =G30 -> 0 | J30: =IF(H30=0,0,H30*$F30) -> 0 | K30: =SUM(I30:J30) -> 0 | N30: 27 | O30: =M30 -> 0 | P30: =IF(N30=0,0,N30*$F30) -> 54 | Q30: =SUM(O30:P30) -> 54 | S30: =SUM(K30:L30,Q30:R30) -> 54 | U30: 23 | V30: Бектурганова Н.Н. | W30: Фармакогнозия | X30: =SUMIF($B$9:$B$884,$V30,G$9:G$884) -> 510 | Y30: =SUMIF($B$9:$B$884,$V30,M$9:M$884) -> 570 | Z30: =SUM(X30:Y30) -> 1080 | AB30: =COUNTIF(V$8:V$99,V30) -> 1
C31: 3 | D31: КЛД-21 | E31: 17 | F31: 1 | I31: =G31 -> 0 | J31: =IF(H31=0,0,H31*$F31) -> 0 | K31: =SUM(I31:J31) -> 0 | M31: 6 | N31: 27 | O31: =M31 -> 6 | P31: =IF(N31=0,0,N31*$F31) -> 27 | Q31: =SUM(O31:P31) -> 33 | S31: =SUM(K31:L31,Q31:R31) -> 33 | U31: 24 | V31: Гениевская Н. | W31: Инф болезни | X31: =SUMIF($B$9:$B$884,$V31,G$9:G$884) -> 186 | Y31: =SUMIF($B$9:$B$884,$V31,M$9:M$884) -> 78 | Z31: =SUM(X31:Y31) -> 264 | AB31: =COUNTIF(V$8:V$99,V31) -> 1
C32: 1 | D32: КСД-21 | E32: 24 | F32: =IF(E32<15,1,IF(((E32>=15)*(E32<23)),2,3)) -> 3 | I32: =G32 -> 0 | J32: =IF(H32=0,0,H32*$F32) -> 0 | K32: =SUM(I32:J32) -> 0 | M32: 6 | N32: 36 | O32: =M32 -> 6 | P32: =IF(N32=0,0,N32*$F32) -> 108 | Q32: =SUM(O32:P32) -> 114 | R32: 12 | S32: =SUM(K32:L32,Q32:R32) -> 126 | U32: 25 | V32: Герасимчук А. | W32: ГиГТ | X32: =SUMIF($B$9:$B$884,$V32,G$9:G$884) -> 216 | Y32: =SUMIF($B$9:$B$884,$V32,M$9:M$884) -> 86 | Z32: =SUM(X32:Y32) -> 302 | AB32: =COUNTIF(V$8:V$99,V32) -> 1
C33: 2 | D33: КСД-22 | E33: 18 | F33: =IF(E33<15,1,IF(((E33>=15)*(E33<23)),2,3)) -> 2 | I33: =G33 -> 0 | J33: =IF(H33=0,0,H33*$F33) -> 0 | K33: =SUM(I33:J33) -> 0 | N33: 36 | O33: =M33 -> 0 | P33: =IF(N33=0,0,N33*$F33) -> 72 | Q33: =SUM(O33:P33) -> 72 | R33: 12 | S33: =SUM(K33:L33,Q33:R33) -> 84 | U33: 26 | V33: Дженбекова А. | W33: ПОПД | X33: =SUMIF($B$9:$B$884,$V33,G$9:G$884) -> 383 | Y33: =SUMIF($B$9:$B$884,$V33,M$9:M$884) -> 390 | Z33: =SUM(X33:Y33) -> 773 | AB33: =COUNTIF(V$8:V$99,V33) -> 1
B34: Кучерова В. | G34: =SUM(K35:L36) -> 240 | M34: =SUM(Q35:R36) -> 186 | S34: =SUM(G34:Q34) -> 426 | U34: 27 | V34: Джолдошева Д.Э. | W34: Акушерство | X34: =SUMIF($B$9:$B$884,$V34,G$9:G$884) -> 117 | Y34: =SUMIF($B$9:$B$884,$V34,M$9:M$884) -> 54 | Z34: =SUM(X34:Y34) -> 171 | AB34: =COUNTIF(V$8:V$99,V34) -> 1
C35: 1 | D35: КЛД-31 | E35: 27 | F35: =IF(E35<15,1,IF(((E35>=15)*(E35<23)),2,3)) -> 3 | H35: 36 | J35: =IF(H35=0,0,H35*$F35) -> 108 | K35: =SUM(I35:J35) -> 108 | L35: 12 | N35: 27 | P35: =IF(N35=0,0,N35*$F35) -> 81 | Q35: =SUM(O35:P35) -> 81 | R35: 12 | S35: =SUM(K35:L35,Q35:R35) -> 213 | U35: 28 | V35: Джумабекова Н. | W35: Акушерство | X35: =SUMIF($B$9:$B$884,$V35,G$9:G$884) -> 42 | Y35: =SUMIF($B$9:$B$884,$V35,M$9:M$884) -> 54 | Z35: =SUM(X35:Y35) -> 96 | AB35: =COUNTIF(V$8:V$99,V35) -> 1
C36: 1 | D36: КЛД-32 | E36: 28 | F36: =IF(E36<15,1,IF(((E36>=15)*(E36<23)),2,3)) -> 3 | H36: 36 | J36: =IF(H36=0,0,H36*$F36) -> 108 | K36: =SUM(I36:J36) -> 108 | L36: 12 | N36: 27 | P36: =IF(N36=0,0,N36*$F36) -> 81 | Q36: =SUM(O36:P36) -> 81 | R36: 12 | S36: =SUM(K36:L36,Q36:R36) -> 213 | U36: 29 | V36: Дикамбаев М. | W36: Хирургия | X36: =SUMIF($B$9:$B$884,$V36,G$9:G$884) -> 0 | Y36: =SUMIF($B$9:$B$884,$V36,M$9:M$884) -> 393 | Z36: =SUM(X36:Y36) -> 393 | AB36: =COUNTIF(V$8:V$99,V36) -> 1
B37: 2 | D37: Терапия | G37: =SUM(G38,G44,G50,G52,G55,G57,G60,G63) -> 762 | M37: =SUM(M38,M44,M50,M52,M55,M57,M60,M63) -> 861 | S37: =SUM(S38,S44,S50,S52,S55,S57,S60,S63) -> 1623 | U37: 30 | V37: Жакыпбеков К.Ш. | W37: Хирургия | X37: =SUMIF($B$9:$B$884,$V37,G$9:G$884) -> 393 | Y37: =SUMIF($B$9:$B$884,$V37,M$9:M$884) -> 54 | Z37: =SUM(X37:Y37) -> 447 | AB37: =COUNTIF(V$8:V$99,V37) -> 1
B38: Янхаева З. | G38: =SUM(K39:L43) -> 189 | M38: =SUM(Q39:R43) -> 0 | S38: =SUM(G38:Q38) -> 189 | U38: 31 | V38: Жамангараева Ж.С. | W38: Педиатрия | X38: =SUMIF($B$9:$B$884,$V38,G$9:G$884) -> 192 | Y38: =SUMIF($B$9:$B$884,$V38,M$9:M$884) -> 132 | Z38: =SUM(X38:Y38) -> 324 | AB38: =COUNTIF(V$8:V$99,V38) -> 1
C39: 1 | D39: КЛД-21 | E39: 30 | F39: =IF(E39<15,1,IF(((E39>=15)*(E39<23)),2,3)) -> 3 | G39: 36 | I39: =G39 -> 36 | J39: =IF(H39=0,0,H39*$F39) -> 0 | K39: =SUM(I39:J39) -> 36 | O39: =M39 -> 0 | P39: =IF(N39=0,0,N39*$F39) -> 0 | Q39: =SUM(O39:P39) -> 0 | S39: =SUM(K39:L39,Q39:R39) -> 36 | U39: 32 | V39: Желденбаева Г. | W39: Кырг язык | X39: =SUMIF($B$9:$B$884,$V39,G$9:G$884) -> 304 | Y39: =SUMIF($B$9:$B$884,$V39,M$9:M$884) -> 312 | Z39: =SUM(X39:Y39) -> 616 | AB39: =COUNTIF(V$8:V$99,V39) -> 1
C40: 2 | D40: КСД-31 | E40: 23 | F40: =IF(E40<15,1,IF(((E40>=15)*(E40<23)),2,3)) -> 3 | G40: 12 | H40: 33 | I40: =G40 -> 12 | J40: =IF(H40=0,0,H40*$F40) -> 99 | K40: =SUM(I40:J40) -> 111 | L40: 6 | O40: =M40 -> 0 | P40: =IF(N40=0,0,N40*$F40) -> 0 | Q40: =SUM(O40:P40) -> 0 | S40: =SUM(K40:L40,Q40:R40) -> 117 | U40: 33 | V40: Жидебаева Н.Т. | W40: ОСД | X40: =SUMIF($B$9:$B$884,$V40,G$9:G$884) -> 293 | Y40: =SUMIF($B$9:$B$884,$V40,M$9:M$884) -> 218 | Z40: =SUM(X40:Y40) -> 511 | AB40: =COUNTIF(V$8:V$99,V40) -> 1
C41: 3 | D41: КЛД-41 | E41: 29 | F41: =IF(E41<15,1,IF(((E41>=15)*(E41<23)),2,3)) -> 3 | G41: 18 | I41: =G41 -> 18 | J41: =IF(H41=0,0,H41*$F41) -> 0 | K41: =SUM(I41:J41) -> 18 | O41: =M41 -> 0 | P41: =IF(N41=0,0,N41*$F41) -> 0 | Q41: =SUM(O41:P41) -> 0 | S41: =SUM(K41:L41,Q41:R41) -> 18 | U41: 34 | V41: Жыргалбек к. К. | W41: ОЭФ | X41: =SUMIF($B$9:$B$884,$V41,G$9:G$884) -> 540 | Y41: =SUMIF($B$9:$B$884,$V41,M$9:M$884) -> 540 | Z41: =SUM(X41:Y41) -> 1080 | AB41: =COUNTIF(V$8:V$99,V41) -> 1
C42: 4 | D42: КСД-21 | E42: 24 | F42: =IF(E42<15,1,IF(((E42>=15)*(E42<23)),2,3)) -> 3 | I42: =G42 -> 0 | J42: =IF(H42=0,0,H42*$F42) -> 0 | K42: =SUM(I42:J42) -> 0 | O42: =M42 -> 0 | P42: =IF(N42=0,0,N42*$F42) -> 0 | Q42: =SUM(O42:P42) -> 0 | S42: =SUM(K42:L42,Q42:R42) -> 0 | U42: 35 | V42: Замирбекова К. | W42: ОСД | X42: =SUMIF($B$9:$B$884,$V42,G$9:G$884) -> 447 | Y42: =SUMIF($B$9:$B$884,$V42,M$9:M$884) -> 306 | Z42: =SUM(X42:Y42) -> 753 | AB42: =COUNTIF(V$8:V$99,V42) -> 1
...

Sheet За год
B2: Годовая нагрузка преподавателей | H2: Годовая нагрузка преподавателей | O2: Годовая нагрузка преподавателей
B3: на 2025-2026 учебный год (бюджет) | H3: на 2025-2026 учебный год (контракт) | O3: на 2025-2026 учебный год (бюджет, контракт)
B5: № | C5: Ф.И.О. | D5: I сем | E5: II сем | F5: Всего | H5: № | I5: Ф.И.О. | J5: I сем | K5: II сем | L5: Всего | O5: № | P5: Ф.И.О. | Q5: I сем | R5: II сем | S5: Всего
B6: 1 | C6: Абдиева Ж. | D6: =SUMIF(Бюджет!V$8:V$77,$C6,Бюджет!X$8:X$107) -> 160 | E6: =SUMIF(Бюджет!V$8:V$77,$C6,Бюджет!Y$8:Y$107) -> 118 | F6: =SUM(D6:E6) -> 278 | H6: 1 | I6: Абдиева Ж. | J6: =SUMIF(Контракт!V$8:V$97,$I6,Контракт!X$8:X$136) -> 40 | K6: =SUMIF(Контракт!V$8:V$97,$I6,Контракт!Y$8:Y$136) -> 42 | L6: =SUM(J6:K6) -> 82 | O6: 1 | P6: Абдиева Ж. | Q6: =SUMIF($C$6:$C$121,$P6,D$6:D$121)+SUMIF($I$6:$I$106,$P6,J$6:J$117) -> 200 | R6: =SUMIF($C$6:$C$121,$P6,E$6:E$121)+SUMIF($I$6:$I$106,$P6,K$6:K$117) -> 160 | S6: =SUM(Q6:R6) -> 360 | T6: =S6/720 -> 0.5 | U6: 0.5
B7: 2 | C7: Абдрахманова Ж. | D7: =SUMIF(Бюджет!V$8:V$77,$C7,Бюджет!X$8:X$107) -> 93 | E7: =SUMIF(Бюджет!V$8:V$77,$C7,Бюджет!Y$8:Y$107) -> 0 | F7: =SUM(D7:E7) -> 93 | H7: 2 | I7: Абдрахманова Ж. | J7: =SUMIF(Контракт!V$8:V$97,$I7,Контракт!X$8:X$136) -> 84 | K7: =SUMIF(Контракт!V$8:V$97,$I7,Контракт!Y$8:Y$136) -> 0 | L7: =SUM(J7:K7) -> 84 | O7: 2 | P7: Абдрахманова Ж. | Q7: =SUMIF($C$6:$C$121,$P7,D$6:D$121)+SUMIF($I$6:$I$106,$P7,J$6:J$117) -> 177 | R7: =SUMIF($C$6:$C$121,$P7,E$6:E$121)+SUMIF($I$6:$I$106,$P7,K$6:K$117) -> 0 | S7: =SUM(Q7:R7) -> 177 | T7: =S7/720 -> 0.24583333
B8: 3 | C8: Абдуллаева М.Н. | D8: =SUMIF(Бюджет!V$8:V$77,$C8,Бюджет!X$8:X$107) -> 18 | E8: =SUMIF(Бюджет!V$8:V$77,$C8,Бюджет!Y$8:Y$107) -> 52 | F8: =SUM(D8:E8) -> 70 | H8: 3 | I8: Абдуллаева М.Н. | J8: =SUMIF(Контракт!V$8:V$97,$I8,Контракт!X$8:X$136) -> 24 | K8: =SUMIF(Контракт!V$8:V$97,$I8,Контракт!Y$8:Y$136) -> 66 | L8: =SUM(J8:K8) -> 90 | O8: 3 | P8: Абдуллаева М.Н. | Q8: =SUMIF($C$6:$C$121,$P8,D$6:D$121)+SUMIF($I$6:$I$106,$P8,J$6:J$117) -> 42 | R8: =SUMIF($C$6:$C$121,$P8,E$6:E$121)+SUMIF($I$6:$I$106,$P8,K$6:K$117) -> 118 | S8: =SUM(Q8:R8) -> 160 | T8: =S8/720 -> 0.22222222
B9: 4 | C9: Абдуллаева М.Н. ШТ | D9: =SUMIF(Бюджет!V$8:V$77,$C9,Бюджет!X$8:X$107) -> 12 | E9: =SUMIF(Бюджет!V$8:V$77,$C9,Бюджет!Y$8:Y$107) -> 8 | F9: =SUM(D9:E9) -> 20 | H9: 4 | I9: Абдуллаева М.Н. ШТ | J9: =SUMIF(Контракт!V$8:V$97,$I9,Контракт!X$8:X$136) -> 150 | K9: =SUMIF(Контракт!V$8:V$97,$I9,Контракт!Y$8:Y$136) -> 30 | L9: =SUM(J9:K9) -> 180 | O9: 4 | P9: Абдуллаева М.Н. ШТ | Q9: =SUMIF($C$6:$C$121,$P9,D$6:D$121)+SUMIF($I$6:$I$106,$P9,J$6:J$117) -> 162 | R9: =SUMIF($C$6:$C$121,$P9,E$6:E$121)+SUMIF($I$6:$I$106,$P9,K$6:K$117) -> 38 | S9: =SUM(Q9:R9) -> 200 | T9: =S9/720 -> 0.27777778 | U9: С 1.03.2026 на почасовую
B10: 5 | C10: Абдыкеримова А.Н. | D10: =SUMIF(Бюджет!V$8:V$77,$C10,Бюджет!X$8:X$107) -> 354 | E10: =SUMIF(Бюджет!V$8:V$77,$C10,Бюджет!Y$8:Y$107) -> 296 | F10: =SUM(D10:E10) -> 650 | H10: 5 | I10: Абдыкеримова А.Н. | J10: =SUMIF(Контракт!V$8:V$97,$I10,Контракт!X$8:X$136) -> 30 | K10: =SUMIF(Контракт!V$8:V$97,$I10,Контракт!Y$8:Y$136) -> 400 | L10: =SUM(J10:K10) -> 430 | O10: 5 | P10: Абдыкеримова А.Н. | Q10: =SUMIF($C$6:$C$121,$P10,D$6:D$121)+SUMIF($I$6:$I$106,$P10,J$6:J$117) -> 384 | R10: =SUMIF($C$6:$C$121,$P10,E$6:E$121)+SUMIF($I$6:$I$106,$P10,K$6:K$117) -> 696 | S10: =SUM(Q10:R10) -> 1080 | T10: =S10/720 -> 1.5
B11: 6 | C11: Абдыкеримова К. | D11: =SUMIF(Бюджет!V$8:V$77,$C11,Бюджет!X$8:X$107) -> 243 | E11: =SUMIF(Бюджет!V$8:V$77,$C11,Бюджет!Y$8:Y$107) -> 0 | F11: =SUM(D11:E11) -> 243 | H11: 6 | I11: Абдыкеримова К. | J11: =SUMIF(Контракт!V$8:V$97,$I11,Контракт!X$8:X$136) -> 303 | K11: =SUMIF(Контракт!V$8:V$97,$I11,Контракт!Y$8:Y$136) -> 0 | L11: =SUM(J11:K11) -> 303 | O11: 6 | P11: Абдыкеримова К. | Q11: =SUMIF($C$6:$C$121,$P11,D$6:D$121)+SUMIF($I$6:$I$106,$P11,J$6:J$117) -> 546 | R11: =SUMIF($C$6:$C$121,$P11,E$6:E$121)+SUMIF($I$6:$I$106,$P11,K$6:K$117) -> 0 | S11: =SUM(Q11:R11) -> 546 | T11: =S11/720 -> 0.75833333
B12: 7 | C12: Азизова Н. | D12: =SUMIF(Бюджет!V$8:V$77,$C12,Бюджет!X$8:X$107) -> 261 | E12: =SUMIF(Бюджет!V$8:V$77,$C12,Бюджет!Y$8:Y$107) -> 138 | F12: =SUM(D12:E12) -> 399 | H12: 7 | I12: Азизова Н. | J12: =SUMIF(Контракт!V$8:V$97,$I12,Контракт!X$8:X$136) -> 312 | K12: =SUMIF(Контракт!V$8:V$97,$I12,Контракт!Y$8:Y$136) -> 369 | L12: =SUM(J12:K12) -> 681 | O12: 7 | P12: Азизова Н. | Q12: =SUMIF($C$6:$C$121,$P12,D$6:D$121)+SUMIF($I$6:$I$106,$P12,J$6:J$117) -> 573 | R12: =SUMIF($C$6:$C$121,$P12,E$6:E$121)+SUMIF($I$6:$I$106,$P12,K$6:K$117) -> 507 | S12: =SUM(Q12:R12) -> 1080 | T12: =S12/720 -> 1.5
B13: 8 | C13: Акимканова А. | D13: =SUMIF(Бюджет!V$8:V$77,$C13,Бюджет!X$8:X$107) -> 96 | E13: =SUMIF(Бюджет!V$8:V$77,$C13,Бюджет!Y$8:Y$107) -> 0 | F13: =SUM(D13:E13) -> 96 | H13: 8 | I13: Айбашева А. | J13: =SUMIF(Контракт!V$8:V$97,$I13,Контракт!X$8:X$136) -> 120 | K13: =SUMIF(Контракт!V$8:V$97,$I13,Контракт!Y$8:Y$136) -> 0 | L13: =SUM(J13:K13) -> 120 | O13: 8 | P13: Айбашева А. | Q13: =SUMIF($C$6:$C$121,$P13,D$6:D$121)+SUMIF($I$6:$I$106,$P13,J$6:J$117) -> 120 | R13: =SUMIF($C$6:$C$121,$P13,E$6:E$121)+SUMIF($I$6:$I$106,$P13,K$6:K$117) -> 0 | S13: =SUM(Q13:R13) -> 120 | T13: =S13/720 -> 0.16666667
B14: 9 | C14: Акматова Ж. | D14: =SUMIF(Бюджет!V$8:V$77,$C14,Бюджет!X$8:X$107) -> 0 | E14: =SUMIF(Бюджет!V$8:V$77,$C14,Бюджет!Y$8:Y$107) -> 42 | F14: =SUM(D14:E14) -> 42 | H14: 9 | I14: Акимканова А. | J14: =SUMIF(Контракт!V$8:V$97,$I14,Контракт!X$8:X$136) -> 30 | K14: =SUMIF(Контракт!V$8:V$97,$I14,Контракт!Y$8:Y$136) -> 0 | L14: =SUM(J14:K14) -> 30 | O14: 9 | P14: Акимканова А. | Q14: =SUMIF($C$6:$C$121,$P14,D$6:D$121)+SUMIF($I$6:$I$106,$P14,J$6:J$117) -> 126 | R14: =SUMIF($C$6:$C$121,$P14,E$6:E$121)+SUMIF($I$6:$I$106,$P14,K$6:K$117) -> 0 | S14: =SUM(Q14:R14) -> 126 | T14: =S14/720 -> 0.175
B15: 10 | C15: Акунова Ч. | D15: =SUMIF(Бюджет!V$8:V$77,$C15,Бюджет!X$8:X$107) -> 54 | E15: =SUMIF(Бюджет!V$8:V$77,$C15,Бюджет!Y$8:Y$107) -> 0 | F15: =SUM(D15:E15) -> 54 | H15: 10 | I15: Акматов У.О. | J15: =SUMIF(Контракт!V$8:V$97,$I15,Контракт!X$8:X$136) -> 554 | K15: =SUMIF(Контракт!V$8:V$97,$I15,Контракт!Y$8:Y$136) -> 468 | L15: =SUM(J15:K15) -> 1022 | O15: 10 | P15: Акматов У.О. | Q15: =SUMIF($C$6:$C$121,$P15,D$6:D$121)+SUMIF($I$6:$I$106,$P15,J$6:J$117) -> 554 | R15: =SUMIF($C$6:$C$121,$P15,E$6:E$121)+SUMIF($I$6:$I$106,$P15,K$6:K$117) -> 468 | S15: =SUM(Q15:R15) -> 1022 | T15: =S15/720 -> 1.4194444
B16: 11 | C16: Акунова Ч. ВНЕШТ | D16: =SUMIF(Бюджет!V$8:V$77,$C16,Бюджет!X$8:X$107) -> 0 | E16: =SUMIF(Бюджет!V$8:V$77,$C16,Бюджет!Y$8:Y$107) -> 109 | F16: =SUM(D16:E16) -> 109 | H16: 11 | I16: Акматова Ж. | J16: =SUMIF(Контракт!V$8:V$97,$I16,Контракт!X$8:X$136) -> 33 | K16: =SUMIF(Контракт!V$8:V$97,$I16,Контракт!Y$8:Y$136) -> 0 | L16: =SUM(J16:K16) -> 33 | O16: 11 | P16: Акматова Ж. | Q16: =SUMIF($C$6:$C$121,$P16,D$6:D$121)+SUMIF($I$6:$I$106,$P16,J$6:J$117) -> 33 | R16: =SUMIF($C$6:$C$121,$P16,E$6:E$121)+SUMIF($I$6:$I$106,$P16,K$6:K$117) -> 42 | S16: =SUM(Q16:R16) -> 75 | T16: =S16/720 -> 0.10416667
B17: 12 | C17: Алиева Х.О. | D17: =SUMIF(Бюджет!V$8:V$77,$C17,Бюджет!X$8:X$107) -> 90 | E17: =SUMIF(Бюджет!V$8:V$77,$C17,Бюджет!Y$8:Y$107) -> 225 | F17: =SUM(D17:E17) -> 315 | H17: 12 | I17: Акунова Ч. | J17: =SUMIF(Контракт!V$8:V$97,$I17,Контракт!X$8:X$136) -> 89 | K17: =SUMIF(Контракт!V$8:V$97,$I17,Контракт!Y$8:Y$136) -> 0 | L17: =SUM(J17:K17) -> 89 | O17: 12 | P17: Акунова Ч. | Q17: =SUMIF($C$6:$C$121,$P17,D$6:D$121)+SUMIF($I$6:$I$106,$P17,J$6:J$117) -> 143 | R17: =SUMIF($C$6:$C$121,$P17,E$6:E$121)+SUMIF($I$6:$I$106,$P17,K$6:K$117) -> 0 | S17: =SUM(Q17:R17) -> 143 | T17: =S17/720 -> 0.19861111
B18: 13 | C18: Аманатова А. | D18: =SUMIF(Бюджет!V$8:V$77,$C18,Бюджет!X$8:X$107) -> 156 | E18: =SUMIF(Бюджет!V$8:V$77,$C18,Бюджет!Y$8:Y$107) -> 42 | F18: =SUM(D18:E18) -> 198 | H18: 13 | I18: Акунова Ч. ВНЕШТ | J18: =SUMIF(Контракт!V$8:V$97,$I18,Контракт!X$8:X$136) -> 0 | K18: =SUMIF(Контракт!V$8:V$97,$I18,Контракт!Y$8:Y$136) -> 156 | L18: =SUM(J18:K18) -> 156 | O18: 13 | P18: Акунова Ч. ВНЕШТ | Q18: =SUMIF($C$6:$C$121,$P18,D$6:D$121)+SUMIF($I$6:$I$106,$P18,J$6:J$117) -> 0 | R18: =SUMIF($C$6:$C$121,$P18,E$6:E$121)+SUMIF($I$6:$I$106,$P18,K$6:K$117) -> 265 | S18: =SUM(Q18:R18) -> 265 | T18: =S18/720 -> 0.36805556
B19: 14 | C19: Аманкелдиева А. | D19: =SUMIF(Бюджет!V$8:V$77,$C19,Бюджет!X$8:X$107) -> 81 | E19: =SUMIF(Бюджет!V$8:V$77,$C19,Бюджет!Y$8:Y$107) -> 81 | F19: =SUM(D19:E19) -> 162 | H19: 14 | I19: Алиева Х.О. | J19: =SUMIF(Контракт!V$8:V$97,$I19,Контракт!X$8:X$136) -> 288 | K19: =SUMIF(Контракт!V$8:V$97,$I19,Контракт!Y$8:Y$136) -> 477 | L19: =SUM(J19:K19) -> 765 | O19: 14 | P19: Алиева Х.О. | Q19: =SUMIF($C$6:$C$121,$P19,D$6:D$121)+SUMIF($I$6:$I$106,$P19,J$6:J$117) -> 378 | R19: =SUMIF($C$6:$C$121,$P19,E$6:E$121)+SUMIF($I$6:$I$106,$P19,K$6:K$117) -> 702 | S19: =SUM(Q19:R19) -> 1080 | T19: =S19/720 -> 1.5
B20: 15 | C20: Асаналиева Г. | D20: =SUMIF(Бюджет!V$8:V$77,$C20,Бюджет!X$8:X$107) -> 0 | E20: =SUMIF(Бюджет!V$8:V$77,$C20,Бюджет!Y$8:Y$107) -> 111 | F20: =SUM(D20:E20) -> 111 | H20: 15 | I20: Аманатова А. | J20: =SUMIF(Контракт!V$8:V$97,$I20,Контракт!X$8:X$136) -> 408 | K20: =SUMIF(Контракт!V$8:V$97,$I20,Контракт!Y$8:Y$136) -> 374 | L20: =SUM(J20:K20) -> 782 | O20: 15 | P20: Аманатова А. | Q20: =SUMIF($C$6:$C$121,$P20,D$6:D$121)+SUMIF($I$6:$I$106,$P20,J$6:J$117) -> 564 | R20: =SUMIF($C$6:$C$121,$P20,E$6:E$121)+SUMIF($I$6:$I$106,$P20,K$6:K$117) -> 416 | S20: =SUM(Q20:R20) -> 980 | T20: =S20/720 -> 1.3611111
B21: 16 | C21: Аскарбеков Б. | D21: =SUMIF(Бюджет!V$8:V$77,$C21,Бюджет!X$8:X$107) -> 0 | E21: =SUMIF(Бюджет!V$8:V$77,$C21,Бюджет!Y$8:Y$107) -> 66 | F21: =SUM(D21:E21) -> 66 | H21: 16 | I21: Аманкелдиева А. | J21: =SUMIF(Контракт!V$8:V$97,$I21,Контракт!X$8:X$136) -> 93 | K21: =SUMIF(Контракт!V$8:V$97,$I21,Контракт!Y$8:Y$136) -> 93 | L21: =SUM(J21:K21) -> 186 | O21: 16 | P21: Аманкелдиева А. | Q21: =SUMIF($C$6:$C$121,$P21,D$6:D$121)+SUMIF($I$6:$I$106,$P21,J$6:J$117) -> 174 | R21: =SUMIF($C$6:$C$121,$P21,E$6:E$121)+SUMIF($I$6:$I$106,$P21,K$6:K$117) -> 174 | S21: =SUM(Q21:R21) -> 348 | T21: =S21/720 -> 0.48333333
... B25: 20 | C25: Гениевская Н. | D25: =SUMIF(Бюджет!V$8:V$77,$C25,Бюджет!X$8:X$107) -> 240 | E25: =SUMIF(Бюджет!V$8:V$77,$C25,Бюджет!Y$8:Y$107) -> 207 | F25: =SUM(D25:E25) -> 447 | H25: 20 | I25: Асылбекова А. | J25: =SUMIF(Контракт!V$8:V$97,$I25,Контракт!X$8:X$136) -> 153 | K25: =SUMIF(Контракт!V$8:V$97,$I25,Контракт!Y$8:Y$136) -> 0 | L25: =SUM(J25:K25) -> 153 | O25: 20 | P25: Асылбекова А. | Q25: =SUMIF($C$6:$C$121,$P25,D$6:D$121)+SUMIF($I$6:$I$106,$P25,J$6:J$117) -> 153 | R25: =SUMIF($C$6:$C$121,$P25,E$6:E$121)+SUMIF($I$6:$I$106,$P25,K$6:K$117) -> 0 | S25: =SUM(Q25:R25) -> 153 | T25: =S25/720 -> 0.2125
B26: 21 | C26: Герасимчук А. | D26: =SUMIF(Бюджет!V$8:V$77,$C26,Бюджет!X$8:X$107) -> 333 | E26: =SUMIF(Бюджет!V$8:V$77,$C26,Бюджет!Y$8:Y$107) -> 445 | F26: =SUM(D26:E26) -> 778 | H26: 21 | I26: Аширахманова Г.Б. | J26: =SUMIF(Контракт!V$8:V$97,$I26,Контракт!X$8:X$136) -> 54 | K26: =SUMIF(Контракт!V$8:V$97,$I26,Контракт!Y$8:Y$136) -> 78 | L26: =SUM(J26:K26) -> 132 | O26: 21 | P26: Аширахманова Г.Б. | Q26: =SUMIF($C$6:$C$121,$P26,D$6:D$121)+SUMIF($I$6:$I$106,$P26,J$6:J$117) -> 120 | R26: =SUMIF($C$6:$C$121,$P26,E$6:E$121)+SUMIF($I$6:$I$106,$P26,K$6:K$117) -> 240 | S26: =SUM(Q26:R26) -> 360 | T26: =S26/720 -> 0.5 | U26: 0.5
B27: 22 | C27: Дженбекова А. | D27: =SUMIF(Бюджет!V$8:V$77,$C27,Бюджет!X$8:X$107) -> 118 | E27: =SUMIF(Бюджет!V$8:V$77,$C27,Бюджет!Y$8:Y$107) -> 189 | F27: =SUM(D27:E27) -> 307 | H27: 22 | I27: Бейсенбиева А. | J27: =SUMIF(Контракт!V$8:V$97,$I27,Контракт!X$8:X$136) -> 204 | K27: =SUMIF(Контракт!V$8:V$97,$I27,Контракт!Y$8:Y$136) -> 327 | L27: =SUM(J27:K27) -> 531 | O27: 22 | P27: Бейсенбиева А. | Q27: =SUMIF($C$6:$C$121,$P27,D$6:D$121)+SUMIF($I$6:$I$106,$P27,J$6:J$117) -> 501 | R27: =SUMIF($C$6:$C$121,$P27,E$6:E$121)+SUMIF($I$6:$I$106,$P27,K$6:K$117) -> 579 | S27: =SUM(Q27:R27) -> 1080 | T27: =S27/720 -> 1.5
B28: 23 | C28: Джолдошева Д.Э. | D28: =SUMIF(Бюджет!V$8:V$77,$C28,Бюджет!X$8:X$107) -> 117 | E28: =SUMIF(Бюджет!V$8:V$77,$C28,Бюджет!Y$8:Y$107) -> 81 | F28: =SUM(D28:E28) -> 198 | H28: 23 | I28: Бектурганова Н.Н. | J28: =SUMIF(Контракт!V$8:V$97,$I28,Контракт!X$8:X$136) -> 510 | K28: =SUMIF(Контракт!V$8:V$97,$I28,Контракт!Y$8:Y$136) -> 570 | L28: =SUM(J28:K28) -> 1080 | O28: 23 | P28: Бектурганова Н.Н. | Q28: =SUMIF($C$6:$C$121,$P28,D$6:D$121)+SUMIF($I$6:$I$106,$P28,J$6:J$117) -> 510 | R28: =SUMIF($C$6:$C$121,$P28,E$6:E$121)+SUMIF($I$6:$I$106,$P28,K$6:K$117) -> 570 | S28: =SUM(Q28:R28) -> 1080 | T28: =S28/720 -> 1.5
B29: 24 | C29: Дикамбаев М. | D29: =SUMIF(Бюджет!V$8:V$77,$C29,Бюджет!X$8:X$107) -> 0 | E29: =SUMIF(Бюджет!V$8:V$77,$C29,Бюджет!Y$8:Y$107) -> 177 | F29: =SUM(D29:E29) -> 177 | H29: 24 | I29: Гениевская Н. | J29: =SUMIF(Контракт!V$8:V$97,$I29,Контракт!X$8:X$136) -> 186 | K29: =SUMIF(Контракт!V$8:V$97,$I29,Контракт!Y$8:Y$136) -> 78 | L29: =SUM(J29:K29) -> 264 | O29: 24 | P29: Гениевская Н. | Q29: =SUMIF($C$6:$C$121,$P29,D$6:D$121)+SUMIF($I$6:$I$106,$P29,J$6:J$117) -> 426 | R29: =SUMIF($C$6:$C$121,$P29,E$6:E$121)+SUMIF($I$6:$I$106,$P29,K$6:K$117) -> 285 | S29: =SUM(Q29:R29) -> 711 | T29: =S29/720 -> 0.9875
B30: 25 | C30: Дикамбаев М. ВНЕШ | D30: =SUMIF(Бюджет!V$8:V$77,$C30,Бюджет!X$8:X$107) -> 0 | E30: =SUMIF(Бюджет!V$8:V$77,$C30,Бюджет!Y$8:Y$107) -> 18 | F30: =SUM(D30:E30) -> 18 | H30: 25 | I30: Герасимчук А. | J30: =SUMIF(Контракт!V$8:V$97,$I30,Контракт!X$8:X$136) -> 216 | K30: =SUMIF(Контракт!V$8:V$97,$I30,Контракт!Y$8:Y$136) -> 86 | L30: =SUM(J30:K30) -> 302 | O30: 25 | P30: Герасимчук А. | Q30: =SUMIF($C$6:$C$121,$P30,D$6:D$121)+SUMIF($I$6:$I$106,$P30,J$6:J$117) -> 549 | R30: =SUMIF($C$6:$C$121,$P30,E$6:E$121)+SUMIF($I$6:$I$106,$P30,K$6:K$117) -> 531 | S30: =SUM(Q30:R30) -> 1080 | T30: =S30/720 -> 1.5
B31: 26 | C31: Жакыпбеков К.Ш. | D31: =SUMIF(Бюджет!V$8:V$77,$C31,Бюджет!X$8:X$107) -> 222 | E31: =SUMIF(Бюджет!V$8:V$77,$C31,Бюджет!Y$8:Y$107) -> 66 | F31: =SUM(D31:E31) -> 288 | H31: 26 | I31: Дженбекова А. | J31: =SUMIF(Контракт!V$8:V$97,$I31,Контракт!X$8:X$136) -> 383 | K31: =SUMIF(Контракт!V$8:V$97,$I31,Контракт!Y$8:Y$136) -> 390 | L31: =SUM(J31:K31) -> 773 | O31: 26 | P31: Дженбекова А. | Q31: =SUMIF($C$6:$C$121,$P31,D$6:D$121)+SUMIF($I$6:$I$106,$P31,J$6:J$117) -> 501 | R31: =SUMIF($C$6:$C$121,$P31,E$6:E$121)+SUMIF($I$6:$I$106,$P31,K$6:K$117) -> 579 | S31: =SUM(Q31:R31) -> 1080 | T31: =S31/720 -> 1.5
B32: 27 | C32: Желденбаева Г. | D32: =SUMIF(Бюджет!V$8:V$77,$C32,Бюджет!X$8:X$107) -> 104 | E32: =SUMIF(Бюджет!V$8:V$77,$C32,Бюджет!Y$8:Y$107) -> 0 | F32: =SUM(D32:E32) -> 104 | H32: 27 | I32: Джолдошева Д.Э. | J32: =SUMIF(Контракт!V$8:V$97,$I32,Контракт!X$8:X$136) -> 117 | K32: =SUMIF(Контракт!V$8:V$97,$I32,Контракт!Y$8:Y$136) -> 54 | L32: =SUM(J32:K32) -> 171 | O32: 27 | P32: Джолдошева Д.Э. | Q32: =SUMIF($C$6:$C$121,$P32,D$6:D$121)+SUMIF($I$6:$I$106,$P32,J$6:J$117) -> 234 | R32: =SUMIF($C$6:$C$121,$P32,E$6:E$121)+SUMIF($I$6:$I$106,$P32,K$6:K$117) -> 135 | S32: =SUM(Q32:R32) -> 369 | T32: =S32/720 -> 0.5125
B33: 28 | C33: Жидебаева Н.Т. | D33: =SUMIF(Бюджет!V$8:V$77,$C33,Бюджет!X$8:X$107) -> 278 | E33: =SUMIF(Бюджет!V$8:V$77,$C33,Бюджет!Y$8:Y$107) -> 291 | F33: =SUM(D33:E33) -> 569 | H33: 28 | I33: Джумабекова Н. | J33: =SUMIF(Контракт!V$8:V$97,$I33,Контракт!X$8:X$136) -> 42 | K33: =SUMIF(Контракт!V$8:V$97,$I33,Контракт!Y$8:Y$136) -> 54 | L33: =SUM(J33:K33) -> 96 | O33: 28 | P33: Джумабекова Н. | Q33: =SUMIF($C$6:$C$121,$P33,D$6:D$121)+SUMIF($I$6:$I$106,$P33,J$6:J$117) -> 42 | R33: =SUMIF($C$6:$C$121,$P33,E$6:E$121)+SUMIF($I$6:$I$106,$P33,K$6:K$117) -> 54 | S33: =SUM(Q33:R33) -> 96 | T33: =S33/720 -> 0.13333333
B34: 29 | C34: Замирбекова К. | D34: =SUMIF(Бюджет!V$8:V$77,$C34,Бюджет!X$8:X$107) -> 225 | E34: =SUMIF(Бюджет!V$8:V$77,$C34,Бюджет!Y$8:Y$107) -> 102 | F34: =SUM(D34:E34) -> 327 | H34: 29 | I34: Дикамбаев М. | J34: =SUMIF(Контракт!V$8:V$97,$I34,Контракт!X$8:X$136) -> 0 | K34: =SUMIF(Контракт!V$8:V$97,$I34,Контракт!Y$8:Y$136) -> 393 | L34: =SUM(J34:K34) -> 393 | O34: 29 | P34: Дикамбаев М. | Q34: =SUMIF($C$6:$C$121,$P34,D$6:D$121)+SUMIF($I$6:$I$106,$P34,J$6:J$117) -> 0 | R34: =SUMIF($C$6:$C$121,$P34,E$6:E$121)+SUMIF($I$6:$I$106,$P34,K$6:K$117) -> 570 | S34: =SUM(Q34:R34) -> 570 | T34: =S34/720 -> 0.79166667
B35: 30 | C35: Иманалиева А. | D35: =SUMIF(Бюджет!V$8:V$77,$C35,Бюджет!X$8:X$107) -> 8 | E35: =SUMIF(Бюджет!V$8:V$77,$C35,Бюджет!Y$8:Y$107) -> 0 | F35: =SUM(D35:E35) -> 8 | H35: 30 | I35: Жакыпбеков К.Ш. | J35: =SUMIF(Контракт!V$8:V$97,$I35,Контракт!X$8:X$136) -> 393 | K35: =SUMIF(Контракт!V$8:V$97,$I35,Контракт!Y$8:Y$136) -> 54 | L35: =SUM(J35:K35) -> 447 | O35: 30 | P35: Дикамбаев М. ВНЕШ | Q35: =SUMIF($C$6:$C$121,$P35,D$6:D$121)+SUMIF($I$6:$I$106,$P35,J$6:J$117) -> 0 | R35: =SUMIF($C$6:$C$121,$P35,E$6:E$121)+SUMIF($I$6:$I$106,$P35,K$6:K$117) -> 18 | S35: =SUM(Q35:R35) -> 18
B36: 31 | C36: Исалиева Г.Б. | D36: =SUMIF(Бюджет!V$8:V$77,$C36,Бюджет!X$8:X$107) -> 150 | E36: =SUMIF(Бюджет!V$8:V$77,$C36,Бюджет!Y$8:Y$107) -> 0 | F36: =SUM(D36:E36) -> 150 | H36: 31 | I36: Жамангараева Ж.С. | J36: =SUMIF(Контракт!V$8:V$97,$I36,Контракт!X$8:X$136) -> 192 | K36: =SUMIF(Контракт!V$8:V$97,$I36,Контракт!Y$8:Y$136) -> 132 | L36: =SUM(J36:K36) -> 324 | O36: 31 | P36: Жакыпбеков К.Ш. | Q36: =SUMIF($C$6:$C$121,$P36,D$6:D$121)+SUMIF($I$6:$I$106,$P36,J$6:J$117) -> 615 | R36: =SUMIF($C$6:$C$121,$P36,E$6:E$121)+SUMIF($I$6:$I$106,$P36,K$6:K$117) -> 120 | S36: =SUM(Q36:R36) -> 735 | T36: =S36/720 -> 1.0208333
B37: 32 | C37: Исмаилова З.Д. | D37: =SUMIF(Бюджет!V$8:V$77,$C37,Бюджет!X$8:X$107) -> 128 | E37: =SUMIF(Бюджет!V$8:V$77,$C37,Бюджет!Y$8:Y$107) -> 123 | F37: =SUM(D37:E37) -> 251 | H37: 32 | I37: Желденбаева Г. | J37: =SUMIF(Контракт!V$8:V$97,$I37,Контракт!X$8:X$136) -> 304 | K37: =SUMIF(Контракт!V$8:V$97,$I37,Контракт!Y$8:Y$136) -> 312 | L37: =SUM(J37:K37) -> 616 | O37: 32 | P37: Жамангараева Ж.С. | Q37: =SUMIF($C$6:$C$121,$P37,D$6:D$121)+SUMIF($I$6:$I$106,$P37,J$6:J$117) -> 192 | R37: =SUMIF($C$6:$C$121,$P37,E$6:E$121)+SUMIF($I$6:$I$106,$P37,K$6:K$117) -> 132 | S37: =SUM(Q37:R37) -> 324 | T37: =S37/720 -> 0.45
B38: 33 | C38: Кадыракун у. К. | D38: =SUMIF(Бюджет!V$8:V$77,$C38,Бюджет!X$8:X$107) -> 108 | E38: =SUMIF(Бюджет!V$8:V$77,$C38,Бюджет!Y$8:Y$107) -> 96 | F38: =SUM(D38:E38) -> 204 | H38: 33 | I38: Жидебаева Н.Т. | J38: =SUMIF(Контракт!V$8:V$97,$I38,Контракт!X$8:X$136) -> 293 | K38: =SUMIF(Контракт!V$8:V$97,$I38,Контракт!Y$8:Y$136) -> 218 | L38: =SUM(J38:K38) -> 511 | O38: 33 | P38: Желденбаева Г. | Q38: =SUMIF($C$6:$C$121,$P38,D$6:D$121)+SUMIF($I$6:$I$106,$P38,J$6:J$117) -> 408 | R38: =SUMIF($C$6:$C$121,$P38,E$6:E$121)+SUMIF($I$6:$I$106,$P38,K$6:K$117) -> 312 | S38: =SUM(Q38:R38) -> 720 | T38: =S38/720 -> 1 | U38: 1
B39: 34 | C39: Карыбаев Т. | D39: =SUMIF(Бюджет!V$8:V$77,$C39,Бюджет!X$8:X$107) -> 99 | E39: =SUMIF(Бюджет!V$8:V$77,$C39,Бюджет!Y$8:Y$107) -> 0 | F39: =SUM(D39:E39) -> 99 | H39: 34 | I39: Жыргалбек к. К. | J39: =SUMIF(Контракт!V$8:V$97,$I39,Контракт!X$8:X$136) -> 540 | K39: =SUMIF(Контракт!V$8:V$97,$I39,Контракт!Y$8:Y$136) -> 540 | L39: =SUM(J39:K39) -> 1080 | O39: 34 | P39: Жидебаева Н.Т. | Q39: =SUMIF($C$6:$C$121,$P39,D$6:D$121)+SUMIF($I$6:$I$106,$P39,J$6:J$117) -> 571 | R39: =SUMIF($C$6:$C$121,$P39,E$6:E$121)+SUMIF($I$6:$I$106,$P39,K$6:K$117) -> 509 | S39: =SUM(Q39:R39) -> 1080 | T39: =S39/720 -> 1.5
B40: 35 | C40: Карыбаева М. | D40: =SUMIF(Бюджет!V$8:V$77,$C40,Бюджет!X$8:X$107) -> 114 | E40: =SUMIF(Бюджет!V$8:V$77,$C40,Бюджет!Y$8:Y$107) -> 0 | F40: =SUM(D40:E40) -> 114 | H40: 35 | I40: Замирбекова К. | J40: =SUMIF(Контракт!V$8:V$97,$I40,Контракт!X$8:X$136) -> 447 | K40: =SUMIF(Контракт!V$8:V$97,$I40,Контракт!Y$8:Y$136) -> 306 | L40: =SUM(J40:K40) -> 753 | O40: 35 | P40: Жыргалбек к. К. | Q40: =SUMIF($C$6:$C$121,$P40,D$6:D$121)+SUMIF($I$6:$I$106,$P40,J$6:J$117) -> 540 | R40: =SUMIF($C$6:$C$121,$P40,E$6:E$121)+SUMIF($I$6:$I$106,$P40,K$6:K$117) -> 540 | S40: =SUM(Q40:R40) -> 1080 | T40: =S40/720 -> 1.5
B41: 36 | C41: Касеева Н. | D41: =SUMIF(Бюджет!V$8:V$77,$C41,Бюджет!X$8:X$107) -> 228 | E41: =SUMIF(Бюджет!V$8:V$77,$C41,Бюджет!Y$8:Y$107) -> 84 | F41: =SUM(D41:E41) -> 312 | H41: 36 | I41: Иманалиева А. | J41: =SUMIF(Контракт!V$8:V$97,$I41,Контракт!X$8:X$136) -> 120 | K41: =SUMIF(Контракт!V$8:V$97,$I41,Контракт!Y$8:Y$136) -> 78 | L41: =SUM(J41:K41) -> 198 | O41: 36 | P41: Замирбекова К. | Q41: =SUMIF($C$6:$C$121,$P41,D$6:D$121)+SUMIF($I$6:$I$106,$P41,J$6:J$117) -> 672 | R41: =SUMIF($C$6:$C$121,$P41,E$6:E$121)+SUMIF($I$6:$I$106,$P41,K$6:K$117) -> 408 | S41: =SUM(Q41:R41) -> 1080 | T41: =S41/720 -> 1.5
B42: 37 | C42: Кубатова А. | D42: =SUMIF(Бюджет!V$8:V$77,$C42,Бюджет!X$8:X$107) -> 432 | E42: =SUMIF(Бюджет!V$8:V$77,$C42,Бюджет!Y$8:Y$107) -> 319 | F42: =SUM(D42:E42) -> 751 | H42: 37 | I42: Исабекова Н. | J42: =SUMIF(Контракт!V$8:V$97,$I42,Контракт!X$8:X$136) -> 0 | K42: =SUMIF(Контракт!V$8:V$97,$I42,Контракт!Y$8:Y$136) -> 288 | L42: =SUM(J42:K42) -> 288 | O42: 37 | P42: Иманалиева А. | Q42: =SUMIF($C$6:$C$121,$P42,D$6:D$121)+SUMIF($I$6:$I$106,$P42,J$6:J$117) -> 128 | R42: =SUMIF($C$6:$C$121,$P42,E$6:E$121)+SUMIF($I$6:$I$106,$P42,K$6:K$117) -> 78 | S42: =SUM(Q42:R42) -> 206 | T42: =S42/720 -> 0.28611111
B43: 38 | C43: Кудайбергенова Э. | D43: =SUMIF(Бюджет!V$8:V$77,$C43,Бюджет!X$8:X$107) -> 153 | E43: =SUMIF(Бюджет!V$8:V$77,$C43,Бюджет!Y$8:Y$107) -> 0 | F43: =SUM(D43:E43) -> 153 | H43: 38 | I43: Исалиева Г.Б. | J43: =SUMIF(Контракт!V$8:V$97,$I43,Контракт!X$8:X$136) -> 228 | K43: =SUMIF(Контракт!V$8:V$97,$I43,Контракт!Y$8:Y$136) -> 342 | L43: =SUM(J43:K43) -> 570 | O43: 38 | P43: Исабекова Н. | Q43: =SUMIF($C$6:$C$121,$P43,D$6:D$121)+SUMIF($I$6:$I$106,$P43,J$6:J$117) -> 0 | R43: =SUMIF($C$6:$C$121,$P43,E$6:E$121)+SUMIF($I$6:$I$106,$P43,K$6:K$117) -> 288 | S43: =SUM(Q43:R43) -> 288 | T43: =S43/720 -> 0.4 | U43: Пал помощь, Инф бол, желательно бюджет
B44: 39 | C44: Кулукеева Д. | D44: =SUMIF(Бюджет!V$8:V$77,$C44,Бюджет!X$8:X$107) -> 90 | E44: =SUMIF(Бюджет!V$8:V$77,$C44,Бюджет!Y$8:Y$107) -> 192 | F44: =SUM(D44:E44) -> 282 | H44: 39 | I44: Исмаилова З.Д. | J44: =SUMIF(Контракт!V$8:V$97,$I44,Контракт!X$8:X$136) -> 114 | K44: =SUMIF(Контракт!V$8:V$97,$I44,Контракт!Y$8:Y$136) -> 94 | L44: =SUM(J44:K44) -> 208 | O44: 39 | P44: Исалиева Г.Б. | Q44: =SUMIF($C$6:$C$121,$P44,D$6:D$121)+SUMIF($I$6:$I$106,$P44,J$6:J$117) -> 378 | R44: =SUMIF($C$6:$C$121,$P44,E$6:E$121)+SUMIF($I$6:$I$106,$P44,K$6:K$117) -> 342 | S44: =SUM(Q44:R44) -> 720 | T44: =S44/720 -> 1 | U44: 1
B45: 40 | C45: Кучерова В. | D45: =SUMIF(Бюджет!V$8:V$77,$C45,Бюджет!X$8:X$107) -> 291 | E45: =SUMIF(Бюджет!V$8:V$77,$C45,Бюджет!Y$8:Y$107) -> 306 | F45: =SUM(D45:E45) -> 597 | H45: 40 | I45: Кадыракун у. К. | J45: =SUMIF(Контракт!V$8:V$97,$I45,Контракт!X$8:X$136) -> 320 | K45: =SUMIF(Контракт!V$8:V$97,$I45,Контракт!Y$8:Y$136) -> 36 | L45: =SUM(J45:K45) -> 356 | O45: 40 | P45: Исмаилова З.Д. | Q45: =SUMIF($C$6:$C$121,$P45,D$6:D$121)+SUMIF($I$6:$I$106,$P45,J$6:J$117) -> 242 | R45: =SUMIF($C$6:$C$121,$P45,E$6:E$121)+SUMIF($I$6:$I$106,$P45,K$6:K$117) -> 217 | S45: =SUM(Q45:R45) -> 459 | T45: =S45/720 -> 0.6375 | U45: 1
...

Sheet Отделения-Циклы
B2: Фарм | E2: Сестринское дело | H2: Лаб диагностика | K2: Акушерское дело | N2: Лечебное дело | Q2: Ортопедическая стоматология
B3: Штат | E3: Штат | H3: Штат | K3: Штат | N3: Штат | Q3: Штат
B4: 1 | C4: Мамралиева Самара | E4: 1 | F4: Акиева Аида | H4: 1 | I4: Омурбек к. Махабат | K4: 1 | L4: Кубатова Айнура | N4: 1 | O4: Осмоналиева Мавлюда | Q4: 1 | R4: Мусаева Эльдана
B5: 2 | C5: Абдыкеримова А | E5: 2 | F5: Абдиева Жыпар | H5: 2 | I5: Асанов Арген | K5: 2 | L5: Алиева Х. | N5: 2 | O5: Исмаилова Зина | Q5: 2 | R5: Кубатбеков Кубанычбек
B6: 3 | C6: Бектурганова Назгул | E6: 3 | F6: Карыбаева М. | H6: 3 | I6: Герасимчук Аня | K6: 3 | L6: Аширахманова Гульмира | N6: 3 | O6: Дикамбаев М. | Q6: 3 | R6: Кулукеева Динара
B7: 4 | C7: Жыргалбек к Клара | E7: 4 | F7: Аманатова Айгул | H7: 4 | I7: Касеева Назира | K7: 4 | L7: Жийдебаева Нурзат | N7: 4 | O7: Султаналиева Ч. | Q7: 4 | R7: Кадыракун у Калыс
B8: 5 | C8: Калдыбаева Динара | E8: 5 | F8: Бейсембиева Айгерим | H8: 5 | I8: Молдалиева Бактыгул | K8: 5 | L8: Исалиева Гульжан | N8: 5 | O8: Жакыпбеков Канимет | Q8: 5 | R8: Дженбекова Алтынай
B9: 6 | C9: Шайымбетова М. | E9: 6 | F9: Гениевская Наталья | H9: 6 | I9: Быкиева Э. | K9: 6 | L9: Кучерова Вероника | N9: 6 | O9: Желденбаева Гульзат | Q9: 6 | R9: Акматов Үсөн
B10: 7 | C10: Осмоналиева Гульжан | E10: 7 | F10: Замирбекова К. | H10: 7 | I10: Эрик к. А. | K10: 7 | L10: Орускулова Т. Р. | N10: 7 | O10: Сарыбаева Чолпон | Q10: 7 | R10: Чынгышбаев Эмир
B11: 8 | C11: Турсунбаева Акжолтой | K11: 8 | L11: Суюмбаева А.И. | N11: 8 | O11: Кенжебаева Гулумкан | Q11: 8 | R11: Акимканова Адинай
B12: 9 | C12: Шайлообек к. Жанылмырза | L12: Токтогулова Мадина | N12: 9 | O12: Махмедов Исламбек
B13: 10 | C13: Курманбетова Айзат | N13: 10 | O13: Мушрапилова Д.
D16: Сестринское дело | H16: Лаб диагностика | K16: Акушерское дело | N16: Лечебное дело | Q16: Ортопедическая стоматология
D17: 1 | E17: Хадисова О.С. | H17: 1 | I17: Эсаналиева Ч. | K17: 1 | L17: Эрмеева А. | N17: 1 | O17: Аманкелдиева А. | Q17: 1 | R17: Эшпаев Т.
D18: 2 | E18: Гениевская Н. | K18: 2 | L18: Акматова Ж. | N18: 2 | O18: Джолдошева Д.Э.
D19: 3 | E19: Майрамбек к. А. | K19: 3 | L19: Шертаева Н. | N19: 3 | O19: Кадыракун у. К.
D20: 4 | E20: Янхаева Я. | K20: 4 | L20: Джумабекова Н. | N20: 4 | O20: Нурлан к. А.
D21: 5 | E21: Иманалиева А. | N21: 5 | O21: Сурабаев Э.
D22: 6 | E22: Жамангараева Ж.С.
D23: 7 | E23: Исабекова Н.
D24: 8 | E24: Керимахунова Д.

Sheet Категории
C2: Годовая нагрузка преподавателей | P2: Годовая нагрузка преподавателей | AC2: Преподаватели
C3: на 2024-2025 учебный год | P3: на 2024-2025 учебный год | AC3: на 2024-2025 учебный год
C5: Бюджетное отделение | P5: Контрактное отделение | AC5: Штат | AF5: Внештат
AC6: № | AD6: Ф.И.О. | AF6: № | AG6: Ф.И.О.
C7: Штат | I7: Внештат | P7: Штат | V7: Внештат | AC7: 1 | AD7: Абдиева Ж. | AF7: 1 | AG7: Абдыкеримова К.
C8: № | D8: Ф.И.О. | E8: I сем | F8: II сем | G8: Всего | I8: № | J8: Ф.И.О. | K8: I сем | L8: II сем | M8: Всего | P8: № | Q8: Ф.И.О. | R8: I сем | S8: II сем | T8: Всего | V8: № | W8: Ф.И.О. | X8: I сем | Y8: II сем | Z8: Всего | AC8: 2 | AD8: Абдыкеримова А.Н. | AF8: 2 | AG8: Айбашева А.С.
C9: 1 | D9: Абдиева Ж. | E9: =SUMIF('За год'!$C$6:$C$86,$D9,'За год'!D$6:D$86) -> 160 | F9: =SUMIF('За год'!$C$6:$C$86,$D9,'За год'!E$6:E$86) -> 118 | G9: =SUMIF('За год'!$C$6:$C$86,$D9,'За год'!F$6:F$86) -> 278 | I9: 1 | J9: Абдыкеримова К. | K9: =SUMIF('За год'!$C$6:$C$106,$J9,'За год'!D$6:D$106) -> 243 | L9: =SUMIF('За год'!$C$6:$C$106,$J9,'За год'!E$6:E$106) -> 0 | M9: =SUMIF('За год'!$C$6:$C$106,$J9,'За год'!F$6:F$106) -> 243 | P9: 1 | Q9: Абдиева Ж. | R9: =SUMIF('За год'!$I$6:$I$107,$Q9,'За год'!J$6:J$123) -> 40 | S9: =SUMIF('За год'!$I$6:$I$107,$Q9,'За год'!K$6:K$123) -> 42 | T9: =SUMIF('За год'!$I$6:$I$107,$Q9,'За год'!L$6:L$123) -> 82 | V9: 1 | W9: Абдыкеримова К. | X9: =SUMIF('За год'!$I$6:$I$107,$W9,'За год'!J$6:J$123) -> 303 | Y9: =SUMIF('За год'!$I$6:$I$107,$W9,'За год'!K$6:K$123) -> 0 | Z9: =SUMIF('За год'!$I$6:$I$107,$W9,'За год'!L$6:L$123) -> 303 | AC9: 3 | AD9: Абдышева Н. | AF9: 3 | AG9: Акматова Ж.
